Workbook

Sheet Shrinkage
B1: Zone | C1: city_name_ | D1: Store Name | E1: CLM | F1: IM | G1: locationtype2 | H1: Adj_Amt | I1: FCC_Bin_Amt | J1: Other_Bin_Amt | K1: Shortpick_Amt | L1: RTO_Loss | M1: PP PO Closed (curr+prev) | N1: PP STO Closed (curr+prev) | O1: PP Canc Closed (curr+prev) | P1: Total Inhouse
B2: South1 | C2: Bengaluru | D2: BLR-27th Main Road | E2: =IF(D2="","",IFERROR(INDEX('CLM & IM Mapping'!$B$2:$B$270,MATCH(TRIM(D2),'CLM & IM Mapping'!$A$2:$A$270,0)),"Not Mapped")) -> Saddam Hussain | F2: =IF(D2="","",IFERROR(INDEX('CLM & IM Mapping'!$C$2:$C$270,MATCH(TRIM(D2),'CLM & IM Mapping'!$A$2:$A$270,0)),"Not Mapped")) -> Un Mapped | G2: RETAIL_STORE | H2: -22532 | I2: 2440 | J2: 0 | K2: 0 | L2: 697 | M2: 0 | N2: 0 | O2: 0 | P2: -19395
B3: South1 | C3: Bengaluru | D3: BLR-BELLANDUR-4 | E3: =IF(D3="","",IFERROR(INDEX('CLM & IM Mapping'!$B$2:$B$270,MATCH(TRIM(D3),'CLM & IM Mapping'!$A$2:$A$270,0)),"Not Mapped")) -> Ashwath S | F3: =IF(D3="","",IFERROR(INDEX('CLM & IM Mapping'!$C$2:$C$270,MATCH(TRIM(D3),'CLM & IM Mapping'!$A$2:$A$270,0)),"Not Mapped")) -> Kantha Kumar | G3: RETAIL_STORE | H3: 21341 | I3: 9514 | J3: 308 | K3: 0 | L3: 0 | M3: 0 | N3: 1394 | O3: 0 | P3: 32557
B4: South1 | C4: Bengaluru | D4: BLR-Margosa road | E4: =IF(D4="","",IFERROR(INDEX('CLM & IM Mapping'!$B$2:$B$270,MATCH(TRIM(D4),'CLM & IM Mapping'!$A$2:$A$270,0)),"Not Mapped")) -> Vijay M | F4: =IF(D4="","",IFERROR(INDEX('CLM & IM Mapping'!$C$2:$C$270,MATCH(TRIM(D4),'CLM & IM Mapping'!$A$2:$A$270,0)),"Not Mapped")) -> Kantha Kumar | G4: RETAIL_STORE | H4: -11044 | I4: 4177 | J4: 0 | K4: 197 | L4: 686 | M4: 0 | N4: 0 | O4: 348 | P4: -5636
B5: South1 | C5: Bengaluru | D5: BLR-Nehru Nagar SS | E5: =IF(D5="","",IFERROR(INDEX('CLM & IM Mapping'!$B$2:$B$270,MATCH(TRIM(D5),'CLM & IM Mapping'!$A$2:$A$270,0)),"Not Mapped")) -> Arun Raj | F5: =IF(D5="","",IFERROR(INDEX('CLM & IM Mapping'!$C$2:$C$270,MATCH(TRIM(D5),'CLM & IM Mapping'!$A$2:$A$270,0)),"Not Mapped")) -> Simon Manoharan | G5: SUPERSTORE | H5: -2036 | I5: 111 | J5: 0 | K5: 0 | L5: 523 | M5: 0 | N5: 17559 | O5: 0 | P5: 16158
B6: South1 | C6: Bengaluru | D6: BLR-Tippenahalli | E6: =IF(D6="","",IFERROR(INDEX('CLM & IM Mapping'!$B$2:$B$270,MATCH(TRIM(D6),'CLM & IM Mapping'!$A$2:$A$270,0)),"Not Mapped")) -> Akshay P | F6: =IF(D6="","",IFERROR(INDEX('CLM & IM Mapping'!$C$2:$C$270,MATCH(TRIM(D6),'CLM & IM Mapping'!$A$2:$A$270,0)),"Not Mapped")) -> Srittam Dhal | G6: RETAIL_STORE | H6: -1395 | I6: 8104 | J6: 0 | K6: 0 | L6: 573 | M6: 0 | N6: 0 | O6: 0 | P6: 7282
B7: South1 | C7: Bengaluru | D7: BLR-Attibele | E7: =IF(D7="","",IFERROR(INDEX('CLM & IM Mapping'!$B$2:$B$270,MATCH(TRIM(D7),'CLM & IM Mapping'!$A$2:$A$270,0)),"Not Mapped")) -> Balaji G | F7: =IF(D7="","",IFERROR(INDEX('CLM & IM Mapping'!$C$2:$C$270,MATCH(TRIM(D7),'CLM & IM Mapping'!$A$2:$A$270,0)),"Not Mapped")) -> Mohammed Akbar | G7: RETAIL_STORE | H7: -46809 | I7: 291 | J7: 0 | K7: 0 | L7: 179 | M7: 0 | N7: 1166 | O7: 0 | P7: -45174
B8: South1 | C8: Bengaluru | D8: BLR-GUNJUR Network | E8: =IF(D8="","",IFERROR(INDEX('CLM & IM Mapping'!$B$2:$B$270,MATCH(TRIM(D8),'CLM & IM Mapping'!$A$2:$A$270,0)),"Not Mapped")) -> Sundaresh S | F8: =IF(D8="","",IFERROR(INDEX('CLM & IM Mapping'!$C$2:$C$270,MATCH(TRIM(D8),'CLM & IM Mapping'!$A$2:$A$270,0)),"Not Mapped")) -> Un Mapped | G8: RETAIL_STORE | H8: -14078 | I8: 1038 | J8: 0 | K8: 0 | L8: 62 | M8: 0 | N8: 1375 | O8: 506 | P8: -11098
B9: South1 | C9: Bengaluru | D9: BLR-RAGHAVENDRA LAYOUT NETWORK 2 | E9: =IF(D9="","",IFERROR(INDEX('CLM & IM Mapping'!$B$2:$B$270,MATCH(TRIM(D9),'CLM & IM Mapping'!$A$2:$A$270,0)),"Not Mapped")) -> Suhas N | F9: =IF(D9="","",IFERROR(INDEX('CLM & IM Mapping'!$C$2:$C$270,MATCH(TRIM(D9),'CLM & IM Mapping'!$A$2:$A$270,0)),"Not Mapped")) -> Aravind S | G9: RETAIL_STORE | H9: -12944 | I9: 4491 | J9: 0 | K9: 648 | L9: 0 | M9: 0 | N9: 0 | O9: 0 | P9: -7805
B10: South1 | C10: Bengaluru | D10: BLR-RICHMOND TOWN SS | E10: =IF(D10="","",IFERROR(INDEX('CLM & IM Mapping'!$B$2:$B$270,MATCH(TRIM(D10),'CLM & IM Mapping'!$A$2:$A$270,0)),"Not Mapped")) -> Arun Raj | F10: =IF(D10="","",IFERROR(INDEX('CLM & IM Mapping'!$C$2:$C$270,MATCH(TRIM(D10),'CLM & IM Mapping'!$A$2:$A$270,0)),"Not Mapped")) -> Simon Manoharan | G10: SUPERSTORE | H10: 18075 | I10: 115931 | J10: -13909 | K10: 463 | L10: 14666 | M10: 0 | N10: 0 | O10: 0 | P10: 135225
B11: South1 | C11: Bengaluru | D11: BLR-RR Nagar Network | E11: =IF(D11="","",IFERROR(INDEX('CLM & IM Mapping'!$B$2:$B$270,MATCH(TRIM(D11),'CLM & IM Mapping'!$A$2:$A$270,0)),"Not Mapped")) -> Ravishankar gowda | F11: =IF(D11="","",IFERROR(INDEX('CLM & IM Mapping'!$C$2:$C$270,MATCH(TRIM(D11),'CLM & IM Mapping'!$A$2:$A$270,0)),"Not Mapped")) -> Kishor K | G11: RETAIL_STORE | H11: -12397 | I11: 9854 | J11: 0 | K11: 129 | L11: 321 | M11: 0 | N11: 165 | O11: 0 | P11: -1928
B12: South1 | C12: Bengaluru | D12: BLR-TC Palaya | E12: =IF(D12="","",IFERROR(INDEX('CLM & IM Mapping'!$B$2:$B$270,MATCH(TRIM(D12),'CLM & IM Mapping'!$A$2:$A$270,0)),"Not Mapped")) -> Rizwan Ahmed | F12: =IF(D12="","",IFERROR(INDEX('CLM & IM Mapping'!$C$2:$C$270,MATCH(TRIM(D12),'CLM & IM Mapping'!$A$2:$A$270,0)),"Not Mapped")) -> Un Mapped | G12: RETAIL_STORE | H12: -10959 | I12: 3796 | J12: 0 | K12: 260 | L12: 73 | M12: 0 | N12: 0 | O12: 0 | P12: -6830
B13: South1 | C13: Bengaluru | D13: BLR-Ullal | E13: =IF(D13="","",IFERROR(INDEX('CLM & IM Mapping'!$B$2:$B$270,MATCH(TRIM(D13),'CLM & IM Mapping'!$A$2:$A$270,0)),"Not Mapped")) -> Ravishankar gowda | F13: =IF(D13="","",IFERROR(INDEX('CLM & IM Mapping'!$C$2:$C$270,MATCH(TRIM(D13),'CLM & IM Mapping'!$A$2:$A$270,0)),"Not Mapped")) -> Kishor K | G13: RETAIL_STORE | H13: -1992 | I13: 3967 | J13: 0 | K13: 0 | L13: 0 | M13: 0 | N13: 0 | O13: 0 | P13: 1975
... B260: South1 | C260: Bengaluru | D260: BLR-Pipeline Road | E260: =IF(D260="","",IFERROR(INDEX('CLM & IM Mapping'!$B$2:$B$270,MATCH(TRIM(D260),'CLM & IM Mapping'!$A$2:$A$270,0)),"Not Mapped")) -> Not Mapped | F260: =IF(D260="","",IFERROR(INDEX('CLM & IM Mapping'!$C$2:$C$270,MATCH(TRIM(D260),'CLM & IM Mapping'!$A$2:$A$270,0)),"Not Mapped")) -> Not Mapped | G260: RETAIL_STORE | H260: 0 | I260: 0 | J260: 0 | K260: 0 | L260: 0 | M260: 0 | N260: 0 | O260: 0 | P260: 0

Sheet Inventory Hygiene
B2: store_name | C2: CLM | D2: IM | E2: sub_store_type | F2: planogram_enabled_flag | G2: city_name | H2: Total Bins | I2: CC MTD % | J2: BA MTD % | K2: IA MTD % | L2: CC ACC %
B3: BEL-Sector 12 | C3: =IF(B3="","",IFERROR(INDEX('CLM & IM Mapping'!$B$2:$B$270,MATCH(TRIM(B3),'CLM & IM Mapping'!$A$2:$A$270,0)),"Not Mapped")) -> Majid Kakatikar | D3: =IF(B3="","",IFERROR(INDEX('CLM & IM Mapping'!$C$2:$C$270,MATCH(TRIM(B3),'CLM & IM Mapping'!$A$2:$A$270,0)),"Not Mapped")) -> Kishor K | E3: RETAIL_STORE | F3: No | G3: Belgavi | H3: 6127 | I3: 0.69 | J3: 1 | K3: 1 | L3: 1
B4: BEL-Khanapur Road | C4: =IF(B4="","",IFERROR(INDEX('CLM & IM Mapping'!$B$2:$B$270,MATCH(TRIM(B4),'CLM & IM Mapping'!$A$2:$A$270,0)),"Not Mapped")) -> Majid Kakatikar | D4: =IF(B4="","",IFERROR(INDEX('CLM & IM Mapping'!$C$2:$C$270,MATCH(TRIM(B4),'CLM & IM Mapping'!$A$2:$A$270,0)),"Not Mapped")) -> Kishor K | E4: RETAIL_STORE | F4: No | G4: Belgavi | H4: 6826 | I4: 0.35 | J4: 0.95 | K4: 0.97 | L4: 0.95
B5: BLR-BELLANDUR-4 | C5: =IF(B5="","",IFERROR(INDEX('CLM & IM Mapping'!$B$2:$B$270,MATCH(TRIM(B5),'CLM & IM Mapping'!$A$2:$A$270,0)),"Not Mapped")) -> Ashwath S | D5: =IF(B5="","",IFERROR(INDEX('CLM & IM Mapping'!$C$2:$C$270,MATCH(TRIM(B5),'CLM & IM Mapping'!$A$2:$A$270,0)),"Not Mapped")) -> Kantha Kumar | E5: RETAIL_STORE | F5: Yes | G5: Bengaluru | H5: 5551 | I5: 0.37 | J5: 0.85 | K5: 0.95 | L5: 0.85
B6: BLR-Margosa road | C6: =IF(B6="","",IFERROR(INDEX('CLM & IM Mapping'!$B$2:$B$270,MATCH(TRIM(B6),'CLM & IM Mapping'!$A$2:$A$270,0)),"Not Mapped")) -> Vijay M | D6: =IF(B6="","",IFERROR(INDEX('CLM & IM Mapping'!$C$2:$C$270,MATCH(TRIM(B6),'CLM & IM Mapping'!$A$2:$A$270,0)),"Not Mapped")) -> Kantha Kumar | E6: RETAIL_STORE | F6: Yes | G6: Bengaluru | H6: 4480 | I6: 0.41 | J6: 0.83 | K6: 0.95 | L6: 0.83
B7: BLR-Tippenahalli | C7: =IF(B7="","",IFERROR(INDEX('CLM & IM Mapping'!$B$2:$B$270,MATCH(TRIM(B7),'CLM & IM Mapping'!$A$2:$A$270,0)),"Not Mapped")) -> Akshay P | D7: =IF(B7="","",IFERROR(INDEX('CLM & IM Mapping'!$C$2:$C$270,MATCH(TRIM(B7),'CLM & IM Mapping'!$A$2:$A$270,0)),"Not Mapped")) -> Srittam Dhal | E7: RETAIL_STORE | F7: Yes | G7: Bengaluru | H7: 4636 | I7: 0.86 | J7: 0.79 | K7: 1 | L7: 0.79
B8: BLR-Nehru Nagar SS | C8: =IF(B8="","",IFERROR(INDEX('CLM & IM Mapping'!$B$2:$B$270,MATCH(TRIM(B8),'CLM & IM Mapping'!$A$2:$A$270,0)),"Not Mapped")) -> Arun Raj | D8: =IF(B8="","",IFERROR(INDEX('CLM & IM Mapping'!$C$2:$C$270,MATCH(TRIM(B8),'CLM & IM Mapping'!$A$2:$A$270,0)),"Not Mapped")) -> Simon Manoharan | E8: SUPERSTORE | F8: No | G8: Bengaluru | H8: 13736 | I8: 0.27 | J8: 0.97 | K8: 0.99 | L8: 0.97
B9: BLR-RR Nagar Network | C9: =IF(B9="","",IFERROR(INDEX('CLM & IM Mapping'!$B$2:$B$270,MATCH(TRIM(B9),'CLM & IM Mapping'!$A$2:$A$270,0)),"Not Mapped")) -> Ravishankar gowda | D9: =IF(B9="","",IFERROR(INDEX('CLM & IM Mapping'!$C$2:$C$270,MATCH(TRIM(B9),'CLM & IM Mapping'!$A$2:$A$270,0)),"Not Mapped")) -> Kishor K | E9: RETAIL_STORE | F9: Yes | G9: Bengaluru | H9: 5893 | I9: 0.77 | J9: 0.88 | K9: 0.97 | L9: 0.88
B10: BLR-TC Palaya | C10: =IF(B10="","",IFERROR(INDEX('CLM & IM Mapping'!$B$2:$B$270,MATCH(TRIM(B10),'CLM & IM Mapping'!$A$2:$A$270,0)),"Not Mapped")) -> Rizwan Ahmed | D10: =IF(B10="","",IFERROR(INDEX('CLM & IM Mapping'!$C$2:$C$270,MATCH(TRIM(B10),'CLM & IM Mapping'!$A$2:$A$270,0)),"Not Mapped")) -> Un Mapped | E10: RETAIL_STORE | F10: Yes | G10: Bengaluru | H10: 6360 | I10: 0.54 | J10: 0.89 | K10: 0.96 | L10: 0.89
B11: BLR-Attibele | C11: =IF(B11="","",IFERROR(INDEX('CLM & IM Mapping'!$B$2:$B$270,MATCH(TRIM(B11),'CLM & IM Mapping'!$A$2:$A$270,0)),"Not Mapped")) -> Balaji G | D11: =IF(B11="","",IFERROR(INDEX('CLM & IM Mapping'!$C$2:$C$270,MATCH(TRIM(B11),'CLM & IM Mapping'!$A$2:$A$270,0)),"Not Mapped")) -> Mohammed Akbar | E11: RETAIL_STORE | F11: Yes | G11: Bengaluru | H11: 7445 | I11: 0.95 | J11: 0.94 | K11: 0.97
B12: BLR-RICHMOND TOWN SS | C12: =IF(B12="","",IFERROR(INDEX('CLM & IM Mapping'!$B$2:$B$270,MATCH(TRIM(B12),'CLM & IM Mapping'!$A$2:$A$270,0)),"Not Mapped")) -> Arun Raj | D12: =IF(B12="","",IFERROR(INDEX('CLM & IM Mapping'!$C$2:$C$270,MATCH(TRIM(B12),'CLM & IM Mapping'!$A$2:$A$270,0)),"Not Mapped")) -> Simon Manoharan | E12: SUPERSTORE | F12: No | G12: Bengaluru | H12: 12938 | I12: 0.13 | J12: 0.77 | K12: 0.92 | L12: 0.46
B13: BLR-Mico Layout Network | C13: =IF(B13="","",IFERROR(INDEX('CLM & IM Mapping'!$B$2:$B$270,MATCH(TRIM(B13),'CLM & IM Mapping'!$A$2:$A$270,0)),"Not Mapped")) -> Keshav G | D13: =IF(B13="","",IFERROR(INDEX('CLM & IM Mapping'!$C$2:$C$270,MATCH(TRIM(B13),'CLM & IM Mapping'!$A$2:$A$270,0)),"Not Mapped")) -> Un Mapped | E13: RETAIL_STORE | F13: No | G13: Bengaluru | H13: 5152 | I13: 0.53 | J13: 0.93 | K13: 0.98 | L13: 0.93
B14: BLR-JP Nagar Network | C14: =IF(B14="","",IFERROR(INDEX('CLM & IM Mapping'!$B$2:$B$270,MATCH(TRIM(B14),'CLM & IM Mapping'!$A$2:$A$270,0)),"Not Mapped")) -> Manjunatha V | D14: =IF(B14="","",IFERROR(INDEX('CLM & IM Mapping'!$C$2:$C$270,MATCH(TRIM(B14),'CLM & IM Mapping'!$A$2:$A$270,0)),"Not Mapped")) -> Un Mapped | E14: RETAIL_STORE | F14: Yes | G14: Bengaluru | H14: 6969 | I14: 0.84 | J14: 0.94 | K14: 0.98 | L14: 0.94
B15: BLR-HSR-2 | C15: =IF(B15="","",IFERROR(INDEX('CLM & IM Mapping'!$B$2:$B$270,MATCH(TRIM(B15),'CLM & IM Mapping'!$A$2:$A$270,0)),"Not Mapped")) -> Saddam Hussain | D15: =IF(B15="","",IFERROR(INDEX('CLM & IM Mapping'!$C$2:$C$270,MATCH(TRIM(B15),'CLM & IM Mapping'!$A$2:$A$270,0)),"Not Mapped")) -> Un Mapped | E15: RETAIL_STORE | F15: No | G15: Bengaluru | H15: 5314 | I15: 0.32 | J15: 0.78 | K15: 0.97 | L15: 0.78
B16: BLR-Brookfield Network-2 | C16: =IF(B16="","",IFERROR(INDEX('CLM & IM Mapping'!$B$2:$B$270,MATCH(TRIM(B16),'CLM & IM Mapping'!$A$2:$A$270,0)),"Not Mapped")) -> Silambarasan E | D16: =IF(B16="","",IFERROR(INDEX('CLM & IM Mapping'!$C$2:$C$270,MATCH(TRIM(B16),'CLM & IM Mapping'!$A$2:$A$270,0)),"Not Mapped")) -> Arivind S | E16: RETAIL_STORE | F16: Yes | G16: Bengaluru | H16: 5057 | I16: 0.8 | J16: 0.86 | K16: 0.95 | L16: 0.86
B17: BLR-RICHMOND TOWN | C17: =IF(B17="","",IFERROR(INDEX('CLM & IM Mapping'!$B$2:$B$270,MATCH(TRIM(B17),'CLM & IM Mapping'!$A$2:$A$270,0)),"Not Mapped")) -> Vijay M | D17: =IF(B17="","",IFERROR(INDEX('CLM & IM Mapping'!$C$2:$C$270,MATCH(TRIM(B17),'CLM & IM Mapping'!$A$2:$A$270,0)),"Not Mapped")) -> Kantha Kumar | E17: RETAIL_STORE | F17: Yes | G17: Bengaluru | H17: 5034 | I17: 0.65 | J17: 0.82 | K17: 0.96 | L17: 0.82
B18: BLR-Richmond Town Network | C18: =IF(B18="","",IFERROR(INDEX('CLM & IM Mapping'!$B$2:$B$270,MATCH(TRIM(B18),'CLM & IM Mapping'!$A$2:$A$270,0)),"Not Mapped")) -> Vijay M | D18: =IF(B18="","",IFERROR(INDEX('CLM & IM Mapping'!$C$2:$C$270,MATCH(TRIM(B18),'CLM & IM Mapping'!$A$2:$A$270,0)),"Not Mapped")) -> Kantha Kumar | E18: RETAIL_STORE | F18: No | G18: Bengaluru | H18: 6121 | I18: 0.86 | J18: 0.93 | K18: 0.97 | L18: 0.93
B19: BLR-Banashankari Network | C19: =IF(B19="","",IFERROR(INDEX('CLM & IM Mapping'!$B$2:$B$270,MATCH(TRIM(B19),'CLM & IM Mapping'!$A$2:$A$270,0)),"Not Mapped")) -> Narasimhamurthy R | D19: =IF(B19="","",IFERROR(INDEX('CLM & IM Mapping'!$C$2:$C$270,MATCH(TRIM(B19),'CLM & IM Mapping'!$A$2:$A$270,0)),"Not Mapped")) -> Kishor K | E19: RETAIL_STORE | F19: Yes | G19: Bengaluru | H19: 5783 | I19: 0.57 | J19: 0.86 | K19: 0.95 | L19: 0.86
B20: BLR-Soukya | C20: =IF(B20="","",IFERROR(INDEX('CLM & IM Mapping'!$B$2:$B$270,MATCH(TRIM(B20),'CLM & IM Mapping'!$A$2:$A$270,0)),"Not Mapped")) -> Ashwath S | D20: =IF(B20="","",IFERROR(INDEX('CLM & IM Mapping'!$C$2:$C$270,MATCH(TRIM(B20),'CLM & IM Mapping'!$A$2:$A$270,0)),"Not Mapped")) -> Kantha Kumar | E20: RETAIL_STORE | F20: Yes | G20: Bengaluru | H20: 6865 | I20: 0.53 | J20: 0.95 | K20: 0.98
B21: BLR-Doddakannelli SS | C21: =IF(B21="","",IFERROR(INDEX('CLM & IM Mapping'!$B$2:$B$270,MATCH(TRIM(B21),'CLM & IM Mapping'!$A$2:$A$270,0)),"Not Mapped")) -> Arun Raj | D21: =IF(B21="","",IFERROR(INDEX('CLM & IM Mapping'!$C$2:$C$270,MATCH(TRIM(B21),'CLM & IM Mapping'!$A$2:$A$270,0)),"Not Mapped")) -> Simon Manoharan | E21: SUPERSTORE | F21: No | G21: Bengaluru | H21: 13860 | I21: 0.32 | J21: 0.97 | K21: 0.99 | L21: 0.97
B22: BLR-RAGHAVENDRA LAYOUT | C22: =IF(B22="","",IFERROR(INDEX('CLM & IM Mapping'!$B$2:$B$270,MATCH(TRIM(B22),'CLM & IM Mapping'!$A$2:$A$270,0)),"Not Mapped")) -> Suhas N | D22: =IF(B22="","",IFERROR(INDEX('CLM & IM Mapping'!$C$2:$C$270,MATCH(TRIM(B22),'CLM & IM Mapping'!$A$2:$A$270,0)),"Not Mapped")) -> Aravind S | E22: RETAIL_STORE | F22: Yes | G22: Bengaluru | H22: 4834 | I22: 0.42 | J22: 0.77 | K22: 0.92 | L22: 0.77
B23: BLR-Hope Farm New | C23: =IF(B23="","",IFERROR(INDEX('CLM & IM Mapping'!$B$2:$B$270,MATCH(TRIM(B23),'CLM & IM Mapping'!$A$2:$A$270,0)),"Not Mapped")) -> Ashwath S | D23: =IF(B23="","",IFERROR(INDEX('CLM & IM Mapping'!$C$2:$C$270,MATCH(TRIM(B23),'CLM & IM Mapping'!$A$2:$A$270,0)),"Not Mapped")) -> Kantha Kumar | E23: RETAIL_STORE | F23: Yes | G23: Bengaluru | H23: 7436 | I23: 0.34 | J23: 0.8 | K23: 0.96 | L23: 0.8
B24: BLR-Pipeline road new | C24: =IF(B24="","",IFERROR(INDEX('CLM & IM Mapping'!$B$2:$B$270,MATCH(TRIM(B24),'CLM & IM Mapping'!$A$2:$A$270,0)),"Not Mapped")) -> Manoj Kj | D24: =IF(B24="","",IFERROR(INDEX('CLM & IM Mapping'!$C$2:$C$270,MATCH(TRIM(B24),'CLM & IM Mapping'!$A$2:$A$270,0)),"Not Mapped")) -> Srittam Dhal | E24: RETAIL_STORE | F24: No | G24: Bengaluru | H24: 4962 | I24: 0.86 | J24: 0.89 | K24: 0.97 | L24: 0.89
B25: BLR-SINGASANDRA NEW | C25: =IF(B25="","",IFERROR(INDEX('CLM & IM Mapping'!$B$2:$B$270,MATCH(TRIM(B25),'CLM & IM Mapping'!$A$2:$A$270,0)),"Not Mapped")) -> Balaji G | D25: =IF(B25="","",IFERROR(INDEX('CLM & IM Mapping'!$C$2:$C$270,MATCH(TRIM(B25),'CLM & IM Mapping'!$A$2:$A$270,0)),"Not Mapped")) -> Mohammed Akbar | E25: RETAIL_STORE | F25: Yes | G25: Bengaluru | H25: 5948 | I25: 0.79 | J25: 0.9 | K25: 0.98
B26: BLR-Whitefield Network-2 | C26: =IF(B26="","",IFERROR(INDEX('CLM & IM Mapping'!$B$2:$B$270,MATCH(TRIM(B26),'CLM & IM Mapping'!$A$2:$A$270,0)),"Not Mapped")) -> Basil Scariya | D26: =IF(B26="","",IFERROR(INDEX('CLM & IM Mapping'!$C$2:$C$270,MATCH(TRIM(B26),'CLM & IM Mapping'!$A$2:$A$270,0)),"Not Mapped")) -> Prakash BS | E26: RETAIL_STORE | F26: Yes | G26: Bengaluru | H26: 5311 | I26: 0.49 | J26: 0.85 | K26: 0.96 | L26: 0.85
B27: BLR-Bellandur new | C27: =IF(B27="","",IFERROR(INDEX('CLM & IM Mapping'!$B$2:$B$270,MATCH(TRIM(B27),'CLM & IM Mapping'!$A$2:$A$270,0)),"Not Mapped")) -> Ashwath S | D27: =IF(B27="","",IFERROR(INDEX('CLM & IM Mapping'!$C$2:$C$270,MATCH(TRIM(B27),'CLM & IM Mapping'!$A$2:$A$270,0)),"Not Mapped")) -> Kantha Kumar | E27: RETAIL_STORE | F27: Yes | G27: Bengaluru | H27: 7207 | I27: 0.82 | J27: 0.95 | K27: 0.99 | L27: 0.95
B28: BLR-Kamakshipalya | C28: =IF(B28="","",IFERROR(INDEX('CLM & IM Mapping'!$B$2:$B$270,MATCH(TRIM(B28),'CLM & IM Mapping'!$A$2:$A$270,0)),"Not Mapped")) -> Manoj Kj | D28: =IF(B28="","",IFERROR(INDEX('CLM & IM Mapping'!$C$2:$C$270,MATCH(TRIM(B28),'CLM & IM Mapping'!$A$2:$A$270,0)),"Not Mapped")) -> Srittam Dhal | E28: RETAIL_STORE | F28: Yes | G28: Bengaluru | H28: 6275 | I28: 0.64 | J28: 0.81 | K28: 0.93 | L28: 0.81
B29: BLR-Hadosiddapura | C29: =IF(B29="","",IFERROR(INDEX('CLM & IM Mapping'!$B$2:$B$270,MATCH(TRIM(B29),'CLM & IM Mapping'!$A$2:$A$270,0)),"Not Mapped")) -> Sundaresh S | D29: =IF(B29="","",IFERROR(INDEX('CLM & IM Mapping'!$C$2:$C$270,MATCH(TRIM(B29),'CLM & IM Mapping'!$A$2:$A$270,0)),"Not Mapped")) -> Un Mapped | E29: RETAIL_STORE | F29: Yes | G29: Bengaluru | H29: 7335 | I29: 0.83 | J29: 0.94 | K29: 0.97
B30: BLR-Ramamurthy Nagar Network | C30: =IF(B30="","",IFERROR(INDEX('CLM & IM Mapping'!$B$2:$B$270,MATCH(TRIM(B30),'CLM & IM Mapping'!$A$2:$A$270,0)),"Not Mapped")) -> Rizwan Ahmed | D30: =IF(B30="","",IFERROR(INDEX('CLM & IM Mapping'!$C$2:$C$270,MATCH(TRIM(B30),'CLM & IM Mapping'!$A$2:$A$270,0)),"Not Mapped")) -> Un Mapped | E30: RETAIL_STORE | F30: No | G30: Bengaluru | H30: 4945 | I30: 0.46 | J30: 0.94 | K30: 0.99 | L30: 0.94
B31: BLR-Silicon Town | C31: =IF(B31="","",IFERROR(INDEX('CLM & IM Mapping'!$B$2:$B$270,MATCH(TRIM(B31),'CLM & IM Mapping'!$A$2:$A$270,0)),"Not Mapped")) -> Balaji G | D31: =IF(B31="","",IFERROR(INDEX('CLM & IM Mapping'!$C$2:$C$270,MATCH(TRIM(B31),'CLM & IM Mapping'!$A$2:$A$270,0)),"Not Mapped")) -> Mohammed Akbar | E31: RETAIL_STORE | F31: No | G31: Bengaluru | H31: 6557 | I31: 0.91 | J31: 0.88 | K31: 0.97 | L31: 0.88
B32: BLR-Doddanekundi | C32: =IF(B32="","",IFERROR(INDEX('CLM & IM Mapping'!$B$2:$B$270,MATCH(TRIM(B32),'CLM & IM Mapping'!$A$2:$A$270,0)),"Not Mapped")) -> Basil Scariya | D32: =IF(B32="","",IFERROR(INDEX('CLM & IM Mapping'!$C$2:$C$270,MATCH(TRIM(B32),'CLM & IM Mapping'!$A$2:$A$270,0)),"Not Mapped")) -> Prakash BS | E32: RETAIL_STORE | F32: Yes | G32: Bengaluru | H32: 6269 | I32: 0.62 | J32: 0.88 | K32: 0.96 | L32: 0.88
B33: BLR-Channasandra | C33: =IF(B33="","",IFERROR(INDEX('CLM & IM Mapping'!$B$2:$B$270,MATCH(TRIM(B33),'CLM & IM Mapping'!$A$2:$A$270,0)),"Not Mapped")) -> Ashwath S | D33: =IF(B33="","",IFERROR(INDEX('CLM & IM Mapping'!$C$2:$C$270,MATCH(TRIM(B33),'CLM & IM Mapping'!$A$2:$A$270,0)),"Not Mapped")) -> Kantha Kumar | E33: RETAIL_STORE | F33: No | G33: Bengaluru | H33: 4660 | I33: 0.9 | J33: 0.88 | K33: 0.98 | L33: 0.88
B34: BLR-HEBBAL NEW | C34: =IF(B34="","",IFERROR(INDEX('CLM & IM Mapping'!$B$2:$B$270,MATCH(TRIM(B34),'CLM & IM Mapping'!$A$2:$A$270,0)),"Not Mapped")) -> Girish N | D34: =IF(B34="","",IFERROR(INDEX('CLM & IM Mapping'!$C$2:$C$270,MATCH(TRIM(B34),'CLM & IM Mapping'!$A$2:$A$270,0)),"Not Mapped")) -> Un Mapped | E34: RETAIL_STORE | F34: No | G34: Bengaluru | H34: 7468 | I34: 0.67 | J34: 0.92 | K34: 0.98 | L34: 0.92
B35: BLR-Malleshwaram SS | C35: =IF(B35="","",IFERROR(INDEX('CLM & IM Mapping'!$B$2:$B$270,MATCH(TRIM(B35),'CLM & IM Mapping'!$A$2:$A$270,0)),"Not Mapped")) -> Arun Raj | D35: =IF(B35="","",IFERROR(INDEX('CLM & IM Mapping'!$C$2:$C$270,MATCH(TRIM(B35),'CLM & IM Mapping'!$A$2:$A$270,0)),"Not Mapped")) -> Simon Manoharan | E35: SUPERSTORE | F35: No | G35: Bengaluru | H35: 7680 | I35: 0.14 | J35: 0.76 | K35: 0.96 | L35: 0.46
B36: BLR-CV Raman Nagar SS | C36: =IF(B36="","",IFERROR(INDEX('CLM & IM Mapping'!$B$2:$B$270,MATCH(TRIM(B36),'CLM & IM Mapping'!$A$2:$A$270,0)),"Not Mapped")) -> Arun Raj | D36: =IF(B36="","",IFERROR(INDEX('CLM & IM Mapping'!$C$2:$C$270,MATCH(TRIM(B36),'CLM & IM Mapping'!$A$2:$A$270,0)),"Not Mapped")) -> Simon Manoharan | E36: SUPERSTORE | F36: No | G36: Bengaluru | H36: 11966 | I36: 0.54 | J36: 0.98 | K36: 1 | L36: 0.98
B37: BLR-Teachers colony | C37: =IF(B37="","",IFERROR(INDEX('CLM & IM Mapping'!$B$2:$B$270,MATCH(TRIM(B37),'CLM & IM Mapping'!$A$2:$A$270,0)),"Not Mapped")) -> Saddam Hussain | D37: =IF(B37="","",IFERROR(INDEX('CLM & IM Mapping'!$C$2:$C$270,MATCH(TRIM(B37),'CLM & IM Mapping'!$A$2:$A$270,0)),"Not Mapped")) -> Un Mapped | E37: RETAIL_STORE | F37: No | G37: Bengaluru | H37: 4901 | I37: 0.64 | J37: 0.9 | K37: 0.98 | L37: 0.9
B38: BLR-Narayanapura Network | C38: =IF(B38="","",IFERROR(INDEX('CLM & IM Mapping'!$B$2:$B$270,MATCH(TRIM(B38),'CLM & IM Mapping'!$A$2:$A$270,0)),"Not Mapped")) -> Adhavan Subramani | D38: =IF(B38="","",IFERROR(INDEX('CLM & IM Mapping'!$C$2:$C$270,MATCH(TRIM(B38),'CLM & IM Mapping'!$A$2:$A$270,0)),"Not Mapped")) -> Mohammed Akbar | E38: RETAIL_STORE | F38: Yes | G38: Bengaluru | H38: 5573 | I38: 0.53 | J38: 0.86 | K38: 0.94 | L38: 0.86
B39: BLR-Bellandur-3 | C39: =IF(B39="","",IFERROR(INDEX('CLM & IM Mapping'!$B$2:$B$270,MATCH(TRIM(B39),'CLM & IM Mapping'!$A$2:$A$270,0)),"Not Mapped")) -> Ashwath S | D39: =IF(B39="","",IFERROR(INDEX('CLM & IM Mapping'!$C$2:$C$270,MATCH(TRIM(B39),'CLM & IM Mapping'!$A$2:$A$270,0)),"Not Mapped")) -> Kantha Kumar | E39: RETAIL_STORE | F39: Yes | G39: Bengaluru | H39: 7376 | I39: 0.37 | J39: 0.8 | K39: 0.62 | L39: 0.8
B40: BLR-RWF Yelahanka | C40: =IF(B40="","",IFERROR(INDEX('CLM & IM Mapping'!$B$2:$B$270,MATCH(TRIM(B40),'CLM & IM Mapping'!$A$2:$A$270,0)),"Not Mapped")) -> Akshay P | D40: =IF(B40="","",IFERROR(INDEX('CLM & IM Mapping'!$C$2:$C$270,MATCH(TRIM(B40),'CLM & IM Mapping'!$A$2:$A$270,0)),"Not Mapped")) -> Srittam Dhal | E40: RETAIL_STORE | F40: No | G40: Bengaluru | H40: 6639 | I40: 0.4 | J40: 0.87 | K40: 0.97 | L40: 0.87
B41: BLR-JP Nagar SS | C41: =IF(B41="","",IFERROR(INDEX('CLM & IM Mapping'!$B$2:$B$270,MATCH(TRIM(B41),'CLM & IM Mapping'!$A$2:$A$270,0)),"Not Mapped")) -> Arun Raj | D41: =IF(B41="","",IFERROR(INDEX('CLM & IM Mapping'!$C$2:$C$270,MATCH(TRIM(B41),'CLM & IM Mapping'!$A$2:$A$270,0)),"Not Mapped")) -> Simon Manoharan | E41: SUPERSTORE | F41: No | G41: Bengaluru | H41: 13730 | I41: 0.06 | J41: 0.96 | K41: 0.98 | L41: 0.26
...

Sheet CLM & IM Mapping
A1: Store Names | B1: CLM Updated | C1: New IM Mapping
A2: BLR-Sarjapur New | B2: Saddam Hussain | C2: Un Mapped
A3: BLR-Agrahara Road | B3: Saddam Hussain | C3: Un Mapped
A4: BLR-Sarjapur-2 | B4: Saddam Hussain | C4: Un Mapped
A5: BLR-Doddakannelli | B5: Sundaresh S | C5: Un Mapped
A6: BLR-Carmelaram | B6: Sundaresh S | C6: Un Mapped
A7: BLR-Kasavanahalli | B7: Saddam Hussain | C7: Un Mapped
A8: BLR-Kasturinagar New | B8: Rizwan Ahmed | C8: Un Mapped
A9: BLR-Dooravani Nagar | B9: Rizwan Ahmed | C9: Un Mapped
A10: BLR-TC Palaya | B10: Rizwan Ahmed | C10: Un Mapped
A11: BLR-Banjara Layout | B11: Rizwan Ahmed | C11: Un Mapped
A12: BLR-Ramamurthy Nagar Network | B12: Rizwan Ahmed | C12: Un Mapped
... A270: TIR-Thiru VK Nagar Road | B270: John Britto | C270: Aravind S

Sheet Bad Bins
B2: Row Labels | C2: CLM | D2: IM | E2: DAMAGEBIN | F2: EXPIRYBIN | G2: QUALITYBIN | H2: REINVENTORY-DAMAGEBIN | I2: REINVENTORY-QUALITYBIN | J2: SCRAPBIN | K2: Grand Total | L2: Created_last_24_hours
B3: KOC-Infopark | C3: =IF(B3="","",IFERROR(INDEX('CLM & IM Mapping'!$B$2:$B$270,MATCH(TRIM(B3),'CLM & IM Mapping'!$A$2:$A$270,0)),"Not Mapped")) -> Vishnu V | D3: =IF(B3="","",IFERROR(INDEX('CLM & IM Mapping'!$C$2:$C$270,MATCH(TRIM(B3),'CLM & IM Mapping'!$A$2:$A$270,0)),"Not Mapped")) -> Arivind S | E3: 100 | F3: 1694 | G3: 31 | H3: 8 | I3: 0 | J3: 24 | K3: 1857 | L3: 69
B4: BLR-SHIVAJI NAGAR Network | C4: =IF(B4="","",IFERROR(INDEX('CLM & IM Mapping'!$B$2:$B$270,MATCH(TRIM(B4),'CLM & IM Mapping'!$A$2:$A$270,0)),"Not Mapped")) -> Vijay M | D4: =IF(B4="","",IFERROR(INDEX('CLM & IM Mapping'!$C$2:$C$270,MATCH(TRIM(B4),'CLM & IM Mapping'!$A$2:$A$270,0)),"Not Mapped")) -> Kantha Kumar | E4: 0 | F4: 11 | G4: 0 | H4: 167 | I4: 830 | J4: 44 | K4: 1052 | L4: 655
B5: BLR-Narayanapura | C5: =IF(B5="","",IFERROR(INDEX('CLM & IM Mapping'!$B$2:$B$270,MATCH(TRIM(B5),'CLM & IM Mapping'!$A$2:$A$270,0)),"Not Mapped")) -> Adhavan Subramani | D5: =IF(B5="","",IFERROR(INDEX('CLM & IM Mapping'!$C$2:$C$270,MATCH(TRIM(B5),'CLM & IM Mapping'!$A$2:$A$270,0)),"Not Mapped")) -> Mohammed Akbar | E5: 48 | F5: 594 | G5: 2 | H5: 2 | I5: 12 | J5: 23 | K5: 681 | L5: 681
B6: BLR-Kannamangala | C6: =IF(B6="","",IFERROR(INDEX('CLM & IM Mapping'!$B$2:$B$270,MATCH(TRIM(B6),'CLM & IM Mapping'!$A$2:$A$270,0)),"Not Mapped")) -> Ashwath S | D6: =IF(B6="","",IFERROR(INDEX('CLM & IM Mapping'!$C$2:$C$270,MATCH(TRIM(B6),'CLM & IM Mapping'!$A$2:$A$270,0)),"Not Mapped")) -> Kantha Kumar | E6: 74 | F6: 398 | G6: 7 | H6: 3 | I6: 0 | J6: 191 | K6: 673 | L6: 429
B7: BLR-Brookfield Network-2 | C7: =IF(B7="","",IFERROR(INDEX('CLM & IM Mapping'!$B$2:$B$270,MATCH(TRIM(B7),'CLM & IM Mapping'!$A$2:$A$270,0)),"Not Mapped")) -> Silambarasan E | D7: =IF(B7="","",IFERROR(INDEX('CLM & IM Mapping'!$C$2:$C$270,MATCH(TRIM(B7),'CLM & IM Mapping'!$A$2:$A$270,0)),"Not Mapped")) -> Arivind S | E7: 172 | F7: 430 | G7: 11 | H7: 0 | I7: 15 | J7: 35 | K7: 663 | L7: 240
B8: BLR-Chamrajpet | C8: =IF(B8="","",IFERROR(INDEX('CLM & IM Mapping'!$B$2:$B$270,MATCH(TRIM(B8),'CLM & IM Mapping'!$A$2:$A$270,0)),"Not Mapped")) -> Narasimhamurthy R | D8: =IF(B8="","",IFERROR(INDEX('CLM & IM Mapping'!$C$2:$C$270,MATCH(TRIM(B8),'CLM & IM Mapping'!$A$2:$A$270,0)),"Not Mapped")) -> Kishor K | E8: 85 | F8: 401 | G8: 93 | H8: 3 | I8: 0 | J8: 76 | K8: 658 | L8: 399
B9: BLR-BASAVANAPURA | C9: =IF(B9="","",IFERROR(INDEX('CLM & IM Mapping'!$B$2:$B$270,MATCH(TRIM(B9),'CLM & IM Mapping'!$A$2:$A$270,0)),"Not Mapped")) -> Richard Harris | D9: =IF(B9="","",IFERROR(INDEX('CLM & IM Mapping'!$C$2:$C$270,MATCH(TRIM(B9),'CLM & IM Mapping'!$A$2:$A$270,0)),"Not Mapped")) -> Kantha Kumar | E9: 21 | F9: 85 | G9: 3 | H9: 377 | I9: 100 | J9: 42 | K9: 628 | L9: 203
B10: BLR-HSR Layout New | C10: =IF(B10="","",IFERROR(INDEX('CLM & IM Mapping'!$B$2:$B$270,MATCH(TRIM(B10),'CLM & IM Mapping'!$A$2:$A$270,0)),"Not Mapped")) -> Saddam Hussain | D10: =IF(B10="","",IFERROR(INDEX('CLM & IM Mapping'!$C$2:$C$270,MATCH(TRIM(B10),'CLM & IM Mapping'!$A$2:$A$270,0)),"Not Mapped")) -> Un Mapped | E10: 0 | F10: 86 | G10: 2 | H10: 60 | I10: 429 | J10: 0 | K10: 577 | L10: 356
B11: BLR-Murugeshpalya | C11: =IF(B11="","",IFERROR(INDEX('CLM & IM Mapping'!$B$2:$B$270,MATCH(TRIM(B11),'CLM & IM Mapping'!$A$2:$A$270,0)),"Not Mapped")) -> Keshav G | D11: =IF(B11="","",IFERROR(INDEX('CLM & IM Mapping'!$C$2:$C$270,MATCH(TRIM(B11),'CLM & IM Mapping'!$A$2:$A$270,0)),"Not Mapped")) -> Mohammed Akbar | E11: 1 | F11: 196 | G11: 261 | H11: 78 | I11: 28 | J11: 2 | K11: 566 | L11: 475
B12: BLR-JP Nagar New | C12: =IF(B12="","",IFERROR(INDEX('CLM & IM Mapping'!$B$2:$B$270,MATCH(TRIM(B12),'CLM & IM Mapping'!$A$2:$A$270,0)),"Not Mapped")) -> Manjunatha V | D12: =IF(B12="","",IFERROR(INDEX('CLM & IM Mapping'!$C$2:$C$270,MATCH(TRIM(B12),'CLM & IM Mapping'!$A$2:$A$270,0)),"Not Mapped")) -> Un Mapped | E12: 25 | F12: 181 | G12: 304 | H12: 0 | I12: 0 | J12: 50 | K12: 560 | L12: 560
B13: BLR-RICHMOND TOWN | C13: =IF(B13="","",IFERROR(INDEX('CLM & IM Mapping'!$B$2:$B$270,MATCH(TRIM(B13),'CLM & IM Mapping'!$A$2:$A$270,0)),"Not Mapped")) -> Vijay M | D13: =IF(B13="","",IFERROR(INDEX('CLM & IM Mapping'!$C$2:$C$270,MATCH(TRIM(B13),'CLM & IM Mapping'!$A$2:$A$270,0)),"Not Mapped")) -> Kantha Kumar | E13: 56 | F13: 76 | G13: 96 | H13: 123 | I13: 64 | J13: 112 | K13: 527 | L13: 437
B14: BLR-Yelenahalli | C14: =IF(B14="","",IFERROR(INDEX('CLM & IM Mapping'!$B$2:$B$270,MATCH(TRIM(B14),'CLM & IM Mapping'!$A$2:$A$270,0)),"Not Mapped")) -> Manjunatha V | D14: =IF(B14="","",IFERROR(INDEX('CLM & IM Mapping'!$C$2:$C$270,MATCH(TRIM(B14),'CLM & IM Mapping'!$A$2:$A$270,0)),"Not Mapped")) -> Un Mapped | E14: 15 | F14: 229 | G14: 104 | H14: 14 | I14: 44 | J14: 92 | K14: 498 | L14: 448
B15: BLR-Eldorado | C15: =IF(B15="","",IFERROR(INDEX('CLM & IM Mapping'!$B$2:$B$270,MATCH(TRIM(B15),'CLM & IM Mapping'!$A$2:$A$270,0)),"Not Mapped")) -> Adhavan Subramani | D15: =IF(B15="","",IFERROR(INDEX('CLM & IM Mapping'!$C$2:$C$270,MATCH(TRIM(B15),'CLM & IM Mapping'!$A$2:$A$270,0)),"Not Mapped")) -> Mohammed Akbar | F15: 84 | H15: 194 | I15: 166 | J15: 44 | K15: 488 | L15: 219
B16: BLR-Mico Layout Network | C16: =IF(B16="","",IFERROR(INDEX('CLM & IM Mapping'!$B$2:$B$270,MATCH(TRIM(B16),'CLM & IM Mapping'!$A$2:$A$270,0)),"Not Mapped")) -> Keshav G | D16: =IF(B16="","",IFERROR(INDEX('CLM & IM Mapping'!$C$2:$C$270,MATCH(TRIM(B16),'CLM & IM Mapping'!$A$2:$A$270,0)),"Not Mapped")) -> Un Mapped | E16: 24 | F16: 168 | G16: 114 | H16: 146 | I16: 0 | J16: 2 | K16: 454 | L16: 262
B17: BLR-Mico layout network-2 | C17: =IF(B17="","",IFERROR(INDEX('CLM & IM Mapping'!$B$2:$B$270,MATCH(TRIM(B17),'CLM & IM Mapping'!$A$2:$A$270,0)),"Not Mapped")) -> Raghavendra Vernekar | D17: =IF(B17="","",IFERROR(INDEX('CLM & IM Mapping'!$C$2:$C$270,MATCH(TRIM(B17),'CLM & IM Mapping'!$A$2:$A$270,0)),"Not Mapped")) -> Prakash BS | E17: 30 | F17: 256 | G17: 42 | H17: 16 | I17: 97 | J17: 7 | K17: 448 | L17: 448
B18: BLR-RAGHAVENDRA LAYOUT NETWORK 2 | C18: =IF(B18="","",IFERROR(INDEX('CLM & IM Mapping'!$B$2:$B$270,MATCH(TRIM(B18),'CLM & IM Mapping'!$A$2:$A$270,0)),"Not Mapped")) -> Suhas N | D18: =IF(B18="","",IFERROR(INDEX('CLM & IM Mapping'!$C$2:$C$270,MATCH(TRIM(B18),'CLM & IM Mapping'!$A$2:$A$270,0)),"Not Mapped")) -> Aravind S | E18: 6 | F18: 130 | G18: 21 | H18: 123 | I18: 80 | J18: 85 | K18: 445 | L18: 361
B19: BLR-Banjara Layout | C19: =IF(B19="","",IFERROR(INDEX('CLM & IM Mapping'!$B$2:$B$270,MATCH(TRIM(B19),'CLM & IM Mapping'!$A$2:$A$270,0)),"Not Mapped")) -> Rizwan Ahmed | D19: =IF(B19="","",IFERROR(INDEX('CLM & IM Mapping'!$C$2:$C$270,MATCH(TRIM(B19),'CLM & IM Mapping'!$A$2:$A$270,0)),"Not Mapped")) -> Un Mapped | E19: 0 | F19: 211 | H19: 122 | I19: 61 | J19: 47 | K19: 441 | L19: 330
B20: BLR-Marathahalli-3 | C20: =IF(B20="","",IFERROR(INDEX('CLM & IM Mapping'!$B$2:$B$270,MATCH(TRIM(B20),'CLM & IM Mapping'!$A$2:$A$270,0)),"Not Mapped")) -> Sundaresh S | D20: =IF(B20="","",IFERROR(INDEX('CLM & IM Mapping'!$C$2:$C$270,MATCH(TRIM(B20),'CLM & IM Mapping'!$A$2:$A$270,0)),"Not Mapped")) -> Un Mapped | E20: 26 | F20: 173 | G20: 88 | H20: 23 | I20: 73 | J20: 18 | K20: 401 | L20: 324
B21: BLR-Marathahalli New | C21: =IF(B21="","",IFERROR(INDEX('CLM & IM Mapping'!$B$2:$B$270,MATCH(TRIM(B21),'CLM & IM Mapping'!$A$2:$A$270,0)),"Not Mapped")) -> Basil Scariya | D21: =IF(B21="","",IFERROR(INDEX('CLM & IM Mapping'!$C$2:$C$270,MATCH(TRIM(B21),'CLM & IM Mapping'!$A$2:$A$270,0)),"Not Mapped")) -> Prakash BS | E21: 35 | F21: 56 | G21: 102 | H21: 17 | I21: 0 | J21: 177 | K21: 387 | L21: 364
B22: BLR-TMC Layout | C22: =IF(B22="","",IFERROR(INDEX('CLM & IM Mapping'!$B$2:$B$270,MATCH(TRIM(B22),'CLM & IM Mapping'!$A$2:$A$270,0)),"Not Mapped")) -> Raghavendra Vernekar | D22: =IF(B22="","",IFERROR(INDEX('CLM & IM Mapping'!$C$2:$C$270,MATCH(TRIM(B22),'CLM & IM Mapping'!$A$2:$A$270,0)),"Not Mapped")) -> Prakash BS | E22: 34 | F22: 71 | G22: 13 | H22: 240 | I22: 0 | J22: 28 | K22: 386 | L22: 372
B23: BLR-BHADRAPPA LAYOUT NETWORK | C23: =IF(B23="","",IFERROR(INDEX('CLM & IM Mapping'!$B$2:$B$270,MATCH(TRIM(B23),'CLM & IM Mapping'!$A$2:$A$270,0)),"Not Mapped")) -> Mohaideen DH | D23: =IF(B23="","",IFERROR(INDEX('CLM & IM Mapping'!$C$2:$C$270,MATCH(TRIM(B23),'CLM & IM Mapping'!$A$2:$A$270,0)),"Not Mapped")) -> Mohammed Akbar | E23: 0 | F23: 1 | G23: 0 | H23: 247 | I23: 121 | J23: 13 | K23: 382 | L23: 88
B24: BLR-BTM LAYOUT NEW | C24: =IF(B24="","",IFERROR(INDEX('CLM & IM Mapping'!$B$2:$B$270,MATCH(TRIM(B24),'CLM & IM Mapping'!$A$2:$A$270,0)),"Not Mapped")) -> Raghavendra Vernekar | D24: =IF(B24="","",IFERROR(INDEX('CLM & IM Mapping'!$C$2:$C$270,MATCH(TRIM(B24),'CLM & IM Mapping'!$A$2:$A$270,0)),"Not Mapped")) -> Prakash BS | E24: 68 | F24: 201 | G24: 74 | H24: 2 | I24: 6 | J24: 31 | K24: 382 | L24: 377
B25: BLR-HSR-3 | C25: =IF(B25="","",IFERROR(INDEX('CLM & IM Mapping'!$B$2:$B$270,MATCH(TRIM(B25),'CLM & IM Mapping'!$A$2:$A$270,0)),"Not Mapped")) -> Saddam Hussain | D25: =IF(B25="","",IFERROR(INDEX('CLM & IM Mapping'!$C$2:$C$270,MATCH(TRIM(B25),'CLM & IM Mapping'!$A$2:$A$270,0)),"Not Mapped")) -> Un Mapped | E25: 10 | F25: 3 | G25: 123 | H25: 51 | I25: 88 | J25: 107 | K25: 382 | L25: 339
B26: COI-Sai baba colony | C26: =IF(B26="","",IFERROR(INDEX('CLM & IM Mapping'!$B$2:$B$270,MATCH(TRIM(B26),'CLM & IM Mapping'!$A$2:$A$270,0)),"Not Mapped")) -> John Britto | D26: =IF(B26="","",IFERROR(INDEX('CLM & IM Mapping'!$C$2:$C$270,MATCH(TRIM(B26),'CLM & IM Mapping'!$A$2:$A$270,0)),"Not Mapped")) -> Aravind S | E26: 78 | F26: 125 | G26: 119 | H26: 9 | I26: 2 | J26: 34 | K26: 367 | L26: 157
B27: BLR-Dasarahalli | C27: =IF(B27="","",IFERROR(INDEX('CLM & IM Mapping'!$B$2:$B$270,MATCH(TRIM(B27),'CLM & IM Mapping'!$A$2:$A$270,0)),"Not Mapped")) -> Mohaideen DH | D27: =IF(B27="","",IFERROR(INDEX('CLM & IM Mapping'!$C$2:$C$270,MATCH(TRIM(B27),'CLM & IM Mapping'!$A$2:$A$270,0)),"Not Mapped")) -> Mohammed Akbar | E27: 0 | F27: 16 | G27: 0 | H27: 103 | I27: 179 | J27: 65 | K27: 363 | L27: 171
B28: BLR-Bannerghatta Network 2 | C28: =IF(B28="","",IFERROR(INDEX('CLM & IM Mapping'!$B$2:$B$270,MATCH(TRIM(B28),'CLM & IM Mapping'!$A$2:$A$270,0)),"Not Mapped")) -> Manjunatha V | D28: =IF(B28="","",IFERROR(INDEX('CLM & IM Mapping'!$C$2:$C$270,MATCH(TRIM(B28),'CLM & IM Mapping'!$A$2:$A$270,0)),"Not Mapped")) -> Un Mapped | E28: 37 | F28: 48 | H28: 88 | I28: 50 | J28: 133 | K28: 356 | L28: 263
B29: BLR-Whitefield New | C29: =IF(B29="","",IFERROR(INDEX('CLM & IM Mapping'!$B$2:$B$270,MATCH(TRIM(B29),'CLM & IM Mapping'!$A$2:$A$270,0)),"Not Mapped")) -> Basil Scariya | D29: =IF(B29="","",IFERROR(INDEX('CLM & IM Mapping'!$C$2:$C$270,MATCH(TRIM(B29),'CLM & IM Mapping'!$A$2:$A$270,0)),"Not Mapped")) -> Prakash BS | E29: 77 | F29: 102 | G29: 16 | H29: 80 | I29: 26 | J29: 54 | K29: 355 | L29: 351
B30: BLR-Arekere | C30: =IF(B30="","",IFERROR(INDEX('CLM & IM Mapping'!$B$2:$B$270,MATCH(TRIM(B30),'CLM & IM Mapping'!$A$2:$A$270,0)),"Not Mapped")) -> Manjunatha V | D30: =IF(B30="","",IFERROR(INDEX('CLM & IM Mapping'!$C$2:$C$270,MATCH(TRIM(B30),'CLM & IM Mapping'!$A$2:$A$270,0)),"Not Mapped")) -> Un Mapped | E30: 45 | F30: 130 | G30: 12 | H30: 103 | I30: 10 | J30: 50 | K30: 350 | L30: 340
B31: BLR-ITPL Layout | C31: =IF(B31="","",IFERROR(INDEX('CLM & IM Mapping'!$B$2:$B$270,MATCH(TRIM(B31),'CLM & IM Mapping'!$A$2:$A$270,0)),"Not Mapped")) -> Rizwan Ahmed | D31: =IF(B31="","",IFERROR(INDEX('CLM & IM Mapping'!$C$2:$C$270,MATCH(TRIM(B31),'CLM & IM Mapping'!$A$2:$A$270,0)),"Not Mapped")) -> Prakash BS | E31: 97 | F31: 127 | G31: 4 | H31: 13 | I31: 31 | J31: 78 | K31: 350 | L31: 328
B32: BLR-Bagalakunte | C32: =IF(B32="","",IFERROR(INDEX('CLM & IM Mapping'!$B$2:$B$270,MATCH(TRIM(B32),'CLM & IM Mapping'!$A$2:$A$270,0)),"Not Mapped")) -> Akshay P | D32: =IF(B32="","",IFERROR(INDEX('CLM & IM Mapping'!$C$2:$C$270,MATCH(TRIM(B32),'CLM & IM Mapping'!$A$2:$A$270,0)),"Not Mapped")) -> Srittam Dhal | E32: 68 | F32: 204 | G32: 69 | H32: 4 | I32: 2 | J32: 0 | K32: 347 | L32: 342
B33: KOC-Thrippunithura | C33: =IF(B33="","",IFERROR(INDEX('CLM & IM Mapping'!$B$2:$B$270,MATCH(TRIM(B33),'CLM & IM Mapping'!$A$2:$A$270,0)),"Not Mapped")) -> Vishnu V | D33: =IF(B33="","",IFERROR(INDEX('CLM & IM Mapping'!$C$2:$C$270,MATCH(TRIM(B33),'CLM & IM Mapping'!$A$2:$A$270,0)),"Not Mapped")) -> Arivind S | E33: 15 | F33: 240 | G33: 8 | H33: 18 | I33: 21 | J33: 25 | K33: 327 | L33: 225
B34: BLR-Bellandur-3 | C34: =IF(B34="","",IFERROR(INDEX('CLM & IM Mapping'!$B$2:$B$270,MATCH(TRIM(B34),'CLM & IM Mapping'!$A$2:$A$270,0)),"Not Mapped")) -> Ashwath S | D34: =IF(B34="","",IFERROR(INDEX('CLM & IM Mapping'!$C$2:$C$270,MATCH(TRIM(B34),'CLM & IM Mapping'!$A$2:$A$270,0)),"Not Mapped")) -> Kantha Kumar | E34: 82 | F34: 65 | G34: 18 | H34: 0 | I34: 159 | J34: 0 | K34: 324 | L34: 309
B35: BLR-Richmond Town Network | C35: =IF(B35="","",IFERROR(INDEX('CLM & IM Mapping'!$B$2:$B$270,MATCH(TRIM(B35),'CLM & IM Mapping'!$A$2:$A$270,0)),"Not Mapped")) -> Vijay M | D35: =IF(B35="","",IFERROR(INDEX('CLM & IM Mapping'!$C$2:$C$270,MATCH(TRIM(B35),'CLM & IM Mapping'!$A$2:$A$270,0)),"Not Mapped")) -> Kantha Kumar | E35: 13 | F35: 36 | G35: 1 | H35: 246 | I35: 26 | J35: 0 | K35: 322 | L35: 170
B36: KOC-Aluva | C36: =IF(B36="","",IFERROR(INDEX('CLM & IM Mapping'!$B$2:$B$270,MATCH(TRIM(B36),'CLM & IM Mapping'!$A$2:$A$270,0)),"Not Mapped")) -> Vishnu V | D36: =IF(B36="","",IFERROR(INDEX('CLM & IM Mapping'!$C$2:$C$270,MATCH(TRIM(B36),'CLM & IM Mapping'!$A$2:$A$270,0)),"Not Mapped")) -> Arivind S | E36: 8 | F36: 273 | G36: 0 | H36: 12 | I36: 0 | J36: 22 | K36: 315 | L36: 184
B37: COI-Peelamedu | C37: =IF(B37="","",IFERROR(INDEX('CLM & IM Mapping'!$B$2:$B$270,MATCH(TRIM(B37),'CLM & IM Mapping'!$A$2:$A$270,0)),"Not Mapped")) -> John Britto | D37: =IF(B37="","",IFERROR(INDEX('CLM & IM Mapping'!$C$2:$C$270,MATCH(TRIM(B37),'CLM & IM Mapping'!$A$2:$A$270,0)),"Not Mapped")) -> Aravind S | E37: 3 | F37: 150 | G37: 5 | H37: 12 | I37: 12 | J37: 126 | K37: 308 | L37: 156
B38: BLR-Nehru Nagar | C38: =IF(B38="","",IFERROR(INDEX('CLM & IM Mapping'!$B$2:$B$270,MATCH(TRIM(B38),'CLM & IM Mapping'!$A$2:$A$270,0)),"Not Mapped")) -> Akshay P | D38: =IF(B38="","",IFERROR(INDEX('CLM & IM Mapping'!$C$2:$C$270,MATCH(TRIM(B38),'CLM & IM Mapping'!$A$2:$A$270,0)),"Not Mapped")) -> Srittam Dhal | E38: 43 | F38: 30 | G38: 0 | H38: 57 | I38: 121 | J38: 56 | K38: 307 | L38: 253
B39: BLR-Teachers colony | C39: =IF(B39="","",IFERROR(INDEX('CLM & IM Mapping'!$B$2:$B$270,MATCH(TRIM(B39),'CLM & IM Mapping'!$A$2:$A$270,0)),"Not Mapped")) -> Saddam Hussain | D39: =IF(B39="","",IFERROR(INDEX('CLM & IM Mapping'!$C$2:$C$270,MATCH(TRIM(B39),'CLM & IM Mapping'!$A$2:$A$270,0)),"Not Mapped")) -> Un Mapped | E39: 59 | F39: 85 | G39: 4 | H39: 0 | I39: 14 | J39: 142 | K39: 304 | L39: 244
B40: BLR-Hennur Main | C40: =IF(B40="","",IFERROR(INDEX('CLM & IM Mapping'!$B$2:$B$270,MATCH(TRIM(B40),'CLM & IM Mapping'!$A$2:$A$270,0)),"Not Mapped")) -> Adhavan Subramani | D40: =IF(B40="","",IFERROR(INDEX('CLM & IM Mapping'!$C$2:$C$270,MATCH(TRIM(B40),'CLM & IM Mapping'!$A$2:$A$270,0)),"Not Mapped")) -> Mohammed Akbar | E40: 0 | F40: 90 | G40: 19 | H40: 126 | I40: 1 | J40: 66 | K40: 302 | L40: 298
B41: KZD-Nadakkave | C41: =IF(B41="","",IFERROR(INDEX('CLM & IM Mapping'!$B$2:$B$270,MATCH(TRIM(B41),'CLM & IM Mapping'!$A$2:$A$270,0)),"Not Mapped")) -> Vishnu V | D41: =IF(B41="","",IFERROR(INDEX('CLM & IM Mapping'!$C$2:$C$270,MATCH(TRIM(B41),'CLM & IM Mapping'!$A$2:$A$270,0)),"Not Mapped")) -> Arivind S | E41: 1 | F41: 0 | H41: 0 | I41: 4 | J41: 296 | K41: 301 | L41: 300
...

Sheet RSTO > 48hrs
B1: Row Labels | C1: CLM | D1: IM | E1: c) 48-72 hr | F1: d) 72-96 hr | G1: e) >96 hr | H1: Grand Total | I1: Grand Total
B2: BLR-Hennur New | C2: =IF(B2="","",IFERROR(INDEX('CLM & IM Mapping'!$B$2:$B$270,MATCH(TRIM(B2),'CLM & IM Mapping'!$A$2:$A$270,0)),"Not Mapped")) -> Adhavan Subramani | D2: =IF(B2="","",IFERROR(INDEX('CLM & IM Mapping'!$C$2:$C$270,MATCH(TRIM(B2),'CLM & IM Mapping'!$A$2:$A$270,0)),"Not Mapped")) -> Mohammed Akbar | G2: 1632 | H2: 1632 | I2: 107843.72
B3: BLR-JC Nagar | C3: =IF(B3="","",IFERROR(INDEX('CLM & IM Mapping'!$B$2:$B$270,MATCH(TRIM(B3),'CLM & IM Mapping'!$A$2:$A$270,0)),"Not Mapped")) -> Manoj Kj | D3: =IF(B3="","",IFERROR(INDEX('CLM & IM Mapping'!$C$2:$C$270,MATCH(TRIM(B3),'CLM & IM Mapping'!$A$2:$A$270,0)),"Not Mapped")) -> Srittam Dhal | G3: 882 | H3: 882 | I3: 104241.31
B4: BLR-ITPL Layout | C4: =IF(B4="","",IFERROR(INDEX('CLM & IM Mapping'!$B$2:$B$270,MATCH(TRIM(B4),'CLM & IM Mapping'!$A$2:$A$270,0)),"Not Mapped")) -> Rizwan Ahmed | D4: =IF(B4="","",IFERROR(INDEX('CLM & IM Mapping'!$C$2:$C$270,MATCH(TRIM(B4),'CLM & IM Mapping'!$A$2:$A$270,0)),"Not Mapped")) -> Prakash BS | E4: 62 | G4: 383 | H4: 445 | I4: 97053.76
B5: BLR-Marathalli SS | C5: =IF(B5="","",IFERROR(INDEX('CLM & IM Mapping'!$B$2:$B$270,MATCH(TRIM(B5),'CLM & IM Mapping'!$A$2:$A$270,0)),"Not Mapped")) -> Arun Raj | D5: =IF(B5="","",IFERROR(INDEX('CLM & IM Mapping'!$C$2:$C$270,MATCH(TRIM(B5),'CLM & IM Mapping'!$A$2:$A$270,0)),"Not Mapped")) -> Simon Manoharan | E5: 74 | G5: 143 | H5: 217 | I5: 90995.49
B6: BLR-Banjara Layout | C6: =IF(B6="","",IFERROR(INDEX('CLM & IM Mapping'!$B$2:$B$270,MATCH(TRIM(B6),'CLM & IM Mapping'!$A$2:$A$270,0)),"Not Mapped")) -> Rizwan Ahmed | D6: =IF(B6="","",IFERROR(INDEX('CLM & IM Mapping'!$C$2:$C$270,MATCH(TRIM(B6),'CLM & IM Mapping'!$A$2:$A$270,0)),"Not Mapped")) -> Un Mapped | E6: 111 | G6: 1055 | H6: 1166 | I6: 81078.71
B7: BLR-Dooravani Nagar | C7: =IF(B7="","",IFERROR(INDEX('CLM & IM Mapping'!$B$2:$B$270,MATCH(TRIM(B7),'CLM & IM Mapping'!$A$2:$A$270,0)),"Not Mapped")) -> Rizwan Ahmed | D7: =IF(B7="","",IFERROR(INDEX('CLM & IM Mapping'!$C$2:$C$270,MATCH(TRIM(B7),'CLM & IM Mapping'!$A$2:$A$270,0)),"Not Mapped")) -> Un Mapped | E7: 514 | G7: 32 | H7: 546 | I7: 68476.09
B8: BLR-Nehru Nagar | C8: =IF(B8="","",IFERROR(INDEX('CLM & IM Mapping'!$B$2:$B$270,MATCH(TRIM(B8),'CLM & IM Mapping'!$A$2:$A$270,0)),"Not Mapped")) -> Akshay P | D8: =IF(B8="","",IFERROR(INDEX('CLM & IM Mapping'!$C$2:$C$270,MATCH(TRIM(B8),'CLM & IM Mapping'!$A$2:$A$270,0)),"Not Mapped")) -> Srittam Dhal | E8: 221 | G8: 486 | H8: 707 | I8: 54546.34
B9: BLR-Malleshwaram new | C9: =IF(B9="","",IFERROR(INDEX('CLM & IM Mapping'!$B$2:$B$270,MATCH(TRIM(B9),'CLM & IM Mapping'!$A$2:$A$270,0)),"Not Mapped")) -> Vijay M | D9: =IF(B9="","",IFERROR(INDEX('CLM & IM Mapping'!$C$2:$C$270,MATCH(TRIM(B9),'CLM & IM Mapping'!$A$2:$A$270,0)),"Not Mapped")) -> Kantha Kumar | E9: 407 | H9: 407 | I9: 45794.29
B10: BLR-JP Nagar SS | C10: =IF(B10="","",IFERROR(INDEX('CLM & IM Mapping'!$B$2:$B$270,MATCH(TRIM(B10),'CLM & IM Mapping'!$A$2:$A$270,0)),"Not Mapped")) -> Arun Raj | D10: =IF(B10="","",IFERROR(INDEX('CLM & IM Mapping'!$C$2:$C$270,MATCH(TRIM(B10),'CLM & IM Mapping'!$A$2:$A$270,0)),"Not Mapped")) -> Simon Manoharan | G10: 235 | H10: 235 | I10: 45393.64
B11: BLR-Arekere | C11: =IF(B11="","",IFERROR(INDEX('CLM & IM Mapping'!$B$2:$B$270,MATCH(TRIM(B11),'CLM & IM Mapping'!$A$2:$A$270,0)),"Not Mapped")) -> Manjunatha V | D11: =IF(B11="","",IFERROR(INDEX('CLM & IM Mapping'!$C$2:$C$270,MATCH(TRIM(B11),'CLM & IM Mapping'!$A$2:$A$270,0)),"Not Mapped")) -> Un Mapped | E11: 343 | G11: 304 | H11: 647 | I11: 45135.89
B12: BLR-Marathahalli New | C12: =IF(B12="","",IFERROR(INDEX('CLM & IM Mapping'!$B$2:$B$270,MATCH(TRIM(B12),'CLM & IM Mapping'!$A$2:$A$270,0)),"Not Mapped")) -> Basil Scariya | D12: =IF(B12="","",IFERROR(INDEX('CLM & IM Mapping'!$C$2:$C$270,MATCH(TRIM(B12),'CLM & IM Mapping'!$A$2:$A$270,0)),"Not Mapped")) -> Prakash BS | E12: 83 | G12: 334 | H12: 417 | I12: 40392.6
B13: BLR-Balagere SS | C13: =IF(B13="","",IFERROR(INDEX('CLM & IM Mapping'!$B$2:$B$270,MATCH(TRIM(B13),'CLM & IM Mapping'!$A$2:$A$270,0)),"Not Mapped")) -> Arun Raj | D13: =IF(B13="","",IFERROR(INDEX('CLM & IM Mapping'!$C$2:$C$270,MATCH(TRIM(B13),'CLM & IM Mapping'!$A$2:$A$270,0)),"Not Mapped")) -> Simon Manoharan | G13: 131 | H13: 131 | I13: 40273.88
B14: BLR-Murugeshpalya | C14: =IF(B14="","",IFERROR(INDEX('CLM & IM Mapping'!$B$2:$B$270,MATCH(TRIM(B14),'CLM & IM Mapping'!$A$2:$A$270,0)),"Not Mapped")) -> Keshav G | D14: =IF(B14="","",IFERROR(INDEX('CLM & IM Mapping'!$C$2:$C$270,MATCH(TRIM(B14),'CLM & IM Mapping'!$A$2:$A$270,0)),"Not Mapped")) -> Mohammed Akbar | E14: 48 | F14: 15 | G14: 580 | H14: 643 | I14: 32712.68
B15: BLR-JP Nagar Network-2 | C15: =IF(B15="","",IFERROR(INDEX('CLM & IM Mapping'!$B$2:$B$270,MATCH(TRIM(B15),'CLM & IM Mapping'!$A$2:$A$270,0)),"Not Mapped")) -> Manjunatha V | D15: =IF(B15="","",IFERROR(INDEX('CLM & IM Mapping'!$C$2:$C$270,MATCH(TRIM(B15),'CLM & IM Mapping'!$A$2:$A$270,0)),"Not Mapped")) -> Un Mapped | G15: 267 | H15: 267 | I15: 31035.39
B16: BLR-Brookfield Network-2 | C16: =IF(B16="","",IFERROR(INDEX('CLM & IM Mapping'!$B$2:$B$270,MATCH(TRIM(B16),'CLM & IM Mapping'!$A$2:$A$270,0)),"Not Mapped")) -> Silambarasan E | D16: =IF(B16="","",IFERROR(INDEX('CLM & IM Mapping'!$C$2:$C$270,MATCH(TRIM(B16),'CLM & IM Mapping'!$A$2:$A$270,0)),"Not Mapped")) -> Arivind S | G16: 150 | H16: 150 | I16: 29719.31
B17: BLR-Bagalakunte | C17: =IF(B17="","",IFERROR(INDEX('CLM & IM Mapping'!$B$2:$B$270,MATCH(TRIM(B17),'CLM & IM Mapping'!$A$2:$A$270,0)),"Not Mapped")) -> Akshay P | D17: =IF(B17="","",IFERROR(INDEX('CLM & IM Mapping'!$C$2:$C$270,MATCH(TRIM(B17),'CLM & IM Mapping'!$A$2:$A$270,0)),"Not Mapped")) -> Srittam Dhal | E17: 300 | G17: 122 | H17: 422 | I17: 29420.75
B18: BLR-Tippenahalli | C18: =IF(B18="","",IFERROR(INDEX('CLM & IM Mapping'!$B$2:$B$270,MATCH(TRIM(B18),'CLM & IM Mapping'!$A$2:$A$270,0)),"Not Mapped")) -> Akshay P | D18: =IF(B18="","",IFERROR(INDEX('CLM & IM Mapping'!$C$2:$C$270,MATCH(TRIM(B18),'CLM & IM Mapping'!$A$2:$A$270,0)),"Not Mapped")) -> Srittam Dhal | E18: 103 | F18: 143 | H18: 246 | I18: 28773.12
B19: BLR- Brookefield SS | C19: =IF(B19="","",IFERROR(INDEX('CLM & IM Mapping'!$B$2:$B$270,MATCH(TRIM(B19),'CLM & IM Mapping'!$A$2:$A$270,0)),"Not Mapped")) -> Arun Raj | D19: =IF(B19="","",IFERROR(INDEX('CLM & IM Mapping'!$C$2:$C$270,MATCH(TRIM(B19),'CLM & IM Mapping'!$A$2:$A$270,0)),"Not Mapped")) -> Simon Manoharan | G19: 113 | H19: 113 | I19: 27828.42
B20: BLR-Mathikere | C20: =IF(B20="","",IFERROR(INDEX('CLM & IM Mapping'!$B$2:$B$270,MATCH(TRIM(B20),'CLM & IM Mapping'!$A$2:$A$270,0)),"Not Mapped")) -> Manoj Kj | D20: =IF(B20="","",IFERROR(INDEX('CLM & IM Mapping'!$C$2:$C$270,MATCH(TRIM(B20),'CLM & IM Mapping'!$A$2:$A$270,0)),"Not Mapped")) -> Srittam Dhal | G20: 516 | H20: 516 | I20: 27752.88
B21: BLR-CV RAMAN NAGAR NEW | C21: =IF(B21="","",IFERROR(INDEX('CLM & IM Mapping'!$B$2:$B$270,MATCH(TRIM(B21),'CLM & IM Mapping'!$A$2:$A$270,0)),"Not Mapped")) -> Silambarasan E | D21: =IF(B21="","",IFERROR(INDEX('CLM & IM Mapping'!$C$2:$C$270,MATCH(TRIM(B21),'CLM & IM Mapping'!$A$2:$A$270,0)),"Not Mapped")) -> Arivind S | E21: 3 | G21: 264 | H21: 267 | I21: 25563.77
B22: BLR-SHIVAJI NAGAR Network | C22: =IF(B22="","",IFERROR(INDEX('CLM & IM Mapping'!$B$2:$B$270,MATCH(TRIM(B22),'CLM & IM Mapping'!$A$2:$A$270,0)),"Not Mapped")) -> Vijay M | D22: =IF(B22="","",IFERROR(INDEX('CLM & IM Mapping'!$C$2:$C$270,MATCH(TRIM(B22),'CLM & IM Mapping'!$A$2:$A$270,0)),"Not Mapped")) -> Kantha Kumar | E22: 37 | F22: 46 | G22: 159 | H22: 242 | I22: 24100.68
B23: BLR-RK Hegde Nagar | C23: =IF(B23="","",IFERROR(INDEX('CLM & IM Mapping'!$B$2:$B$270,MATCH(TRIM(B23),'CLM & IM Mapping'!$A$2:$A$270,0)),"Not Mapped")) -> Mohaideen DH | D23: =IF(B23="","",IFERROR(INDEX('CLM & IM Mapping'!$C$2:$C$270,MATCH(TRIM(B23),'CLM & IM Mapping'!$A$2:$A$270,0)),"Not Mapped")) -> Mohammed Akbar | E23: 248 | F23: 1 | H23: 249 | I23: 23064.55
B24: BLR-BHADRAPPA LAYOUT NETWORK | C24: =IF(B24="","",IFERROR(INDEX('CLM & IM Mapping'!$B$2:$B$270,MATCH(TRIM(B24),'CLM & IM Mapping'!$A$2:$A$270,0)),"Not Mapped")) -> Mohaideen DH | D24: =IF(B24="","",IFERROR(INDEX('CLM & IM Mapping'!$C$2:$C$270,MATCH(TRIM(B24),'CLM & IM Mapping'!$A$2:$A$270,0)),"Not Mapped")) -> Mohammed Akbar | F24: 41 | G24: 75 | H24: 116 | I24: 21903.32
B25: BLR-Shivaji nagar New | C25: =IF(B25="","",IFERROR(INDEX('CLM & IM Mapping'!$B$2:$B$270,MATCH(TRIM(B25),'CLM & IM Mapping'!$A$2:$A$270,0)),"Not Mapped")) -> Vijay M | D25: =IF(B25="","",IFERROR(INDEX('CLM & IM Mapping'!$C$2:$C$270,MATCH(TRIM(B25),'CLM & IM Mapping'!$A$2:$A$270,0)),"Not Mapped")) -> Kantha Kumar | F25: 171 | G25: 79 | H25: 250 | I25: 20254.73
B26: BLR-Malleshpalya | C26: =IF(B26="","",IFERROR(INDEX('CLM & IM Mapping'!$B$2:$B$270,MATCH(TRIM(B26),'CLM & IM Mapping'!$A$2:$A$270,0)),"Not Mapped")) -> Silambarasan E | D26: =IF(B26="","",IFERROR(INDEX('CLM & IM Mapping'!$C$2:$C$270,MATCH(TRIM(B26),'CLM & IM Mapping'!$A$2:$A$270,0)),"Not Mapped")) -> Arivind S | E26: 166 | F26: 1 | G26: 240 | H26: 407 | I26: 19335.48
B27: BLR-Narayanapura | C27: =IF(B27="","",IFERROR(INDEX('CLM & IM Mapping'!$B$2:$B$270,MATCH(TRIM(B27),'CLM & IM Mapping'!$A$2:$A$270,0)),"Not Mapped")) -> Adhavan Subramani | D27: =IF(B27="","",IFERROR(INDEX('CLM & IM Mapping'!$C$2:$C$270,MATCH(TRIM(B27),'CLM & IM Mapping'!$A$2:$A$270,0)),"Not Mapped")) -> Mohammed Akbar | E27: 247 | G27: 16 | H27: 263 | I27: 19258.09
B28: BLR-Whitefield New | C28: =IF(B28="","",IFERROR(INDEX('CLM & IM Mapping'!$B$2:$B$270,MATCH(TRIM(B28),'CLM & IM Mapping'!$A$2:$A$270,0)),"Not Mapped")) -> Basil Scariya | D28: =IF(B28="","",IFERROR(INDEX('CLM & IM Mapping'!$C$2:$C$270,MATCH(TRIM(B28),'CLM & IM Mapping'!$A$2:$A$270,0)),"Not Mapped")) -> Prakash BS | E28: 32 | G28: 3 | H28: 35 | I28: 13998.49
B29: BLR-JAYANAGAR New | C29: =IF(B29="","",IFERROR(INDEX('CLM & IM Mapping'!$B$2:$B$270,MATCH(TRIM(B29),'CLM & IM Mapping'!$A$2:$A$270,0)),"Not Mapped")) -> Suhas N | D29: =IF(B29="","",IFERROR(INDEX('CLM & IM Mapping'!$C$2:$C$270,MATCH(TRIM(B29),'CLM & IM Mapping'!$A$2:$A$270,0)),"Not Mapped")) -> Aravind S | E29: 30 | F29: 10 | G29: 57 | H29: 97 | I29: 13851.48
B30: BLR-Seegehalli | C30: =IF(B30="","",IFERROR(INDEX('CLM & IM Mapping'!$B$2:$B$270,MATCH(TRIM(B30),'CLM & IM Mapping'!$A$2:$A$270,0)),"Not Mapped")) -> Richard Harris | D30: =IF(B30="","",IFERROR(INDEX('CLM & IM Mapping'!$C$2:$C$270,MATCH(TRIM(B30),'CLM & IM Mapping'!$A$2:$A$270,0)),"Not Mapped")) -> Kantha Kumar | G30: 42 | H30: 42 | I30: 13670.67
B31: BLR-Aswath Nagar | C31: =IF(B31="","",IFERROR(INDEX('CLM & IM Mapping'!$B$2:$B$270,MATCH(TRIM(B31),'CLM & IM Mapping'!$A$2:$A$270,0)),"Not Mapped")) -> Sundaresh S | D31: =IF(B31="","",IFERROR(INDEX('CLM & IM Mapping'!$C$2:$C$270,MATCH(TRIM(B31),'CLM & IM Mapping'!$A$2:$A$270,0)),"Not Mapped")) -> Un Mapped | E31: 79 | G31: 12 | H31: 91 | I31: 13577.18
B32: BLR-Malleshwaram SS | C32: =IF(B32="","",IFERROR(INDEX('CLM & IM Mapping'!$B$2:$B$270,MATCH(TRIM(B32),'CLM & IM Mapping'!$A$2:$A$270,0)),"Not Mapped")) -> Arun Raj | D32: =IF(B32="","",IFERROR(INDEX('CLM & IM Mapping'!$C$2:$C$270,MATCH(TRIM(B32),'CLM & IM Mapping'!$A$2:$A$270,0)),"Not Mapped")) -> Simon Manoharan | G32: 58 | H32: 58 | I32: 12880.59
B33: BLR-Thyagaraja Nagar | C33: =IF(B33="","",IFERROR(INDEX('CLM & IM Mapping'!$B$2:$B$270,MATCH(TRIM(B33),'CLM & IM Mapping'!$A$2:$A$270,0)),"Not Mapped")) -> Suhas N | D33: =IF(B33="","",IFERROR(INDEX('CLM & IM Mapping'!$C$2:$C$270,MATCH(TRIM(B33),'CLM & IM Mapping'!$A$2:$A$270,0)),"Not Mapped")) -> Aravind S | F33: 112 | H33: 112 | I33: 12850.85
B34: BLR-Kamakshipalya | C34: =IF(B34="","",IFERROR(INDEX('CLM & IM Mapping'!$B$2:$B$270,MATCH(TRIM(B34),'CLM & IM Mapping'!$A$2:$A$270,0)),"Not Mapped")) -> Manoj Kj | D34: =IF(B34="","",IFERROR(INDEX('CLM & IM Mapping'!$C$2:$C$270,MATCH(TRIM(B34),'CLM & IM Mapping'!$A$2:$A$270,0)),"Not Mapped")) -> Srittam Dhal | E34: 163 | G34: 93 | H34: 256 | I34: 12819.34
B35: BLR-Kadarenahalli | C35: =IF(B35="","",IFERROR(INDEX('CLM & IM Mapping'!$B$2:$B$270,MATCH(TRIM(B35),'CLM & IM Mapping'!$A$2:$A$270,0)),"Not Mapped")) -> Raghavendra Vernekar | D35: =IF(B35="","",IFERROR(INDEX('CLM & IM Mapping'!$C$2:$C$270,MATCH(TRIM(B35),'CLM & IM Mapping'!$A$2:$A$270,0)),"Not Mapped")) -> Prakash BS | E35: 39 | G35: 108 | H35: 147 | I35: 11961.78
B36: BLR-CV Raman Nagar Network-2 | C36: =IF(B36="","",IFERROR(INDEX('CLM & IM Mapping'!$B$2:$B$270,MATCH(TRIM(B36),'CLM & IM Mapping'!$A$2:$A$270,0)),"Not Mapped")) -> Silambarasan E | D36: =IF(B36="","",IFERROR(INDEX('CLM & IM Mapping'!$C$2:$C$270,MATCH(TRIM(B36),'CLM & IM Mapping'!$A$2:$A$270,0)),"Not Mapped")) -> Arivind S | E36: 178 | H36: 178 | I36: 11834.6
B37: BLR-Yelenahalli | C37: =IF(B37="","",IFERROR(INDEX('CLM & IM Mapping'!$B$2:$B$270,MATCH(TRIM(B37),'CLM & IM Mapping'!$A$2:$A$270,0)),"Not Mapped")) -> Manjunatha V | D37: =IF(B37="","",IFERROR(INDEX('CLM & IM Mapping'!$C$2:$C$270,MATCH(TRIM(B37),'CLM & IM Mapping'!$A$2:$A$270,0)),"Not Mapped")) -> Un Mapped | E37: 56 | G37: 38 | H37: 94 | I37: 11658.72
B38: BLR-GUNJUR Network | C38: =IF(B38="","",IFERROR(INDEX('CLM & IM Mapping'!$B$2:$B$270,MATCH(TRIM(B38),'CLM & IM Mapping'!$A$2:$A$270,0)),"Not Mapped")) -> Sundaresh S | D38: =IF(B38="","",IFERROR(INDEX('CLM & IM Mapping'!$C$2:$C$270,MATCH(TRIM(B38),'CLM & IM Mapping'!$A$2:$A$270,0)),"Not Mapped")) -> Un Mapped | E38: 2 | G38: 11 | H38: 13 | I38: 11027.58
B39: BLR-Hennur Main | C39: =IF(B39="","",IFERROR(INDEX('CLM & IM Mapping'!$B$2:$B$270,MATCH(TRIM(B39),'CLM & IM Mapping'!$A$2:$A$270,0)),"Not Mapped")) -> Adhavan Subramani | D39: =IF(B39="","",IFERROR(INDEX('CLM & IM Mapping'!$C$2:$C$270,MATCH(TRIM(B39),'CLM & IM Mapping'!$A$2:$A$270,0)),"Not Mapped")) -> Mohammed Akbar | E39: 94 | H39: 94 | I39: 10939.86
B40: BLR-TC Palaya | C40: =IF(B40="","",IFERROR(INDEX('CLM & IM Mapping'!$B$2:$B$270,MATCH(TRIM(B40),'CLM & IM Mapping'!$A$2:$A$270,0)),"Not Mapped")) -> Rizwan Ahmed | D40: =IF(B40="","",IFERROR(INDEX('CLM & IM Mapping'!$C$2:$C$270,MATCH(TRIM(B40),'CLM & IM Mapping'!$A$2:$A$270,0)),"Not Mapped")) -> Un Mapped | G40: 69 | H40: 69 | I40: 10330.25
...

Sheet Recirculation > 24 hrs
B2: Row Labels | C2: CLM | D2: IM | E2: 24-48 hrs | F2: 48-72 hrs | G2: 72-96 hrs | H2: >96 hrs | I2: A2P | J2: P2D | K2: Grand Total
B3: BLR-Hennur New | C3: =IF(B3="","",IFERROR(INDEX('CLM & IM Mapping'!$B$2:$B$270,MATCH(TRIM(B3),'CLM & IM Mapping'!$A$2:$A$270,0)),"Not Mapped")) -> Adhavan Subramani | D3: =IF(B3="","",IFERROR(INDEX('CLM & IM Mapping'!$C$2:$C$270,MATCH(TRIM(B3),'CLM & IM Mapping'!$A$2:$A$270,0)),"Not Mapped")) -> Mohammed Akbar | G3: 3010 | H3: 7631 | I3: 10641 | J3: 0 | K3: 10641
B4: BLR-JP Nagar SS | C4: =IF(B4="","",IFERROR(INDEX('CLM & IM Mapping'!$B$2:$B$270,MATCH(TRIM(B4),'CLM & IM Mapping'!$A$2:$A$270,0)),"Not Mapped")) -> Arun Raj | D4: =IF(B4="","",IFERROR(INDEX('CLM & IM Mapping'!$C$2:$C$270,MATCH(TRIM(B4),'CLM & IM Mapping'!$A$2:$A$270,0)),"Not Mapped")) -> Simon Manoharan | H4: 4863 | I4: 4863 | J4: 0 | K4: 4863
B5: BLR-Balagere SS | C5: =IF(B5="","",IFERROR(INDEX('CLM & IM Mapping'!$B$2:$B$270,MATCH(TRIM(B5),'CLM & IM Mapping'!$A$2:$A$270,0)),"Not Mapped")) -> Arun Raj | D5: =IF(B5="","",IFERROR(INDEX('CLM & IM Mapping'!$C$2:$C$270,MATCH(TRIM(B5),'CLM & IM Mapping'!$A$2:$A$270,0)),"Not Mapped")) -> Simon Manoharan | E5: 408 | G5: 4150 | H5: 1 | I5: 4538 | J5: 21 | K5: 4559
B6: BLR-Bannerghatta Network 2 | C6: =IF(B6="","",IFERROR(INDEX('CLM & IM Mapping'!$B$2:$B$270,MATCH(TRIM(B6),'CLM & IM Mapping'!$A$2:$A$270,0)),"Not Mapped")) -> Manjunatha V | D6: =IF(B6="","",IFERROR(INDEX('CLM & IM Mapping'!$C$2:$C$270,MATCH(TRIM(B6),'CLM & IM Mapping'!$A$2:$A$270,0)),"Not Mapped")) -> Un Mapped | E6: 1595 | G6: 382 | H6: 5 | I6: 1895 | J6: 87 | K6: 1982
B7: BLR-JP Nagar New | C7: =IF(B7="","",IFERROR(INDEX('CLM & IM Mapping'!$B$2:$B$270,MATCH(TRIM(B7),'CLM & IM Mapping'!$A$2:$A$270,0)),"Not Mapped")) -> Manjunatha V | D7: =IF(B7="","",IFERROR(INDEX('CLM & IM Mapping'!$C$2:$C$270,MATCH(TRIM(B7),'CLM & IM Mapping'!$A$2:$A$270,0)),"Not Mapped")) -> Un Mapped | E7: 1822 | I7: 1822 | J7: 0 | K7: 1822
B8: BLR-Whitefield New | C8: =IF(B8="","",IFERROR(INDEX('CLM & IM Mapping'!$B$2:$B$270,MATCH(TRIM(B8),'CLM & IM Mapping'!$A$2:$A$270,0)),"Not Mapped")) -> Basil Scariya | D8: =IF(B8="","",IFERROR(INDEX('CLM & IM Mapping'!$C$2:$C$270,MATCH(TRIM(B8),'CLM & IM Mapping'!$A$2:$A$270,0)),"Not Mapped")) -> Prakash BS | E8: 1598 | G8: 1 | I8: 1599 | J8: 0 | K8: 1599
B9: BLR-Bommasandra | C9: =IF(B9="","",IFERROR(INDEX('CLM & IM Mapping'!$B$2:$B$270,MATCH(TRIM(B9),'CLM & IM Mapping'!$A$2:$A$270,0)),"Not Mapped")) -> Balaji G | D9: =IF(B9="","",IFERROR(INDEX('CLM & IM Mapping'!$C$2:$C$270,MATCH(TRIM(B9),'CLM & IM Mapping'!$A$2:$A$270,0)),"Not Mapped")) -> Mohammed Akbar | E9: 1509 | I9: 1509 | J9: 0 | K9: 1509
B10: BLR-HSR Layout New | C10: =IF(B10="","",IFERROR(INDEX('CLM & IM Mapping'!$B$2:$B$270,MATCH(TRIM(B10),'CLM & IM Mapping'!$A$2:$A$270,0)),"Not Mapped")) -> Saddam Hussain | D10: =IF(B10="","",IFERROR(INDEX('CLM & IM Mapping'!$C$2:$C$270,MATCH(TRIM(B10),'CLM & IM Mapping'!$A$2:$A$270,0)),"Not Mapped")) -> Un Mapped | E10: 1489 | H10: 7 | I10: 1490 | J10: 6 | K10: 1496
B11: BLR-Hegganahalli | C11: =IF(B11="","",IFERROR(INDEX('CLM & IM Mapping'!$B$2:$B$270,MATCH(TRIM(B11),'CLM & IM Mapping'!$A$2:$A$270,0)),"Not Mapped")) -> Manoj Kj | D11: =IF(B11="","",IFERROR(INDEX('CLM & IM Mapping'!$C$2:$C$270,MATCH(TRIM(B11),'CLM & IM Mapping'!$A$2:$A$270,0)),"Not Mapped")) -> Srittam Dhal | E11: 1463 | I11: 1463 | J11: 0 | K11: 1463
B12: BLR-Mico layout network-2 | C12: =IF(B12="","",IFERROR(INDEX('CLM & IM Mapping'!$B$2:$B$270,MATCH(TRIM(B12),'CLM & IM Mapping'!$A$2:$A$270,0)),"Not Mapped")) -> Raghavendra Vernekar | D12: =IF(B12="","",IFERROR(INDEX('CLM & IM Mapping'!$C$2:$C$270,MATCH(TRIM(B12),'CLM & IM Mapping'!$A$2:$A$270,0)),"Not Mapped")) -> Prakash BS | E12: 1222 | G12: 230 | I12: 1426 | J12: 26 | K12: 1452
B13: BLR-Kadugodi | C13: =IF(B13="","",IFERROR(INDEX('CLM & IM Mapping'!$B$2:$B$270,MATCH(TRIM(B13),'CLM & IM Mapping'!$A$2:$A$270,0)),"Not Mapped")) -> Ashwath S | D13: =IF(B13="","",IFERROR(INDEX('CLM & IM Mapping'!$C$2:$C$270,MATCH(TRIM(B13),'CLM & IM Mapping'!$A$2:$A$270,0)),"Not Mapped")) -> Kantha Kumar | E13: 1451 | G13: 1 | I13: 1452 | J13: 0 | K13: 1452
B14: BLR-Vijay Nagar Network | C14: =IF(B14="","",IFERROR(INDEX('CLM & IM Mapping'!$B$2:$B$270,MATCH(TRIM(B14),'CLM & IM Mapping'!$A$2:$A$270,0)),"Not Mapped")) -> Narasimhamurthy R | D14: =IF(B14="","",IFERROR(INDEX('CLM & IM Mapping'!$C$2:$C$270,MATCH(TRIM(B14),'CLM & IM Mapping'!$A$2:$A$270,0)),"Not Mapped")) -> Kishor K | E14: 860 | G14: 259 | H14: 301 | I14: 1420 | J14: 0 | K14: 1420
B15: BLR-RAGHAVENDRA LAYOUT NETWORK | C15: =IF(B15="","",IFERROR(INDEX('CLM & IM Mapping'!$B$2:$B$270,MATCH(TRIM(B15),'CLM & IM Mapping'!$A$2:$A$270,0)),"Not Mapped")) -> Suhas N | D15: =IF(B15="","",IFERROR(INDEX('CLM & IM Mapping'!$C$2:$C$270,MATCH(TRIM(B15),'CLM & IM Mapping'!$A$2:$A$270,0)),"Not Mapped")) -> Aravind S | E15: 765 | G15: 352 | I15: 768 | J15: 349 | K15: 1117
B16: BLR-Richmond Town Network | C16: =IF(B16="","",IFERROR(INDEX('CLM & IM Mapping'!$B$2:$B$270,MATCH(TRIM(B16),'CLM & IM Mapping'!$A$2:$A$270,0)),"Not Mapped")) -> Vijay M | D16: =IF(B16="","",IFERROR(INDEX('CLM & IM Mapping'!$C$2:$C$270,MATCH(TRIM(B16),'CLM & IM Mapping'!$A$2:$A$270,0)),"Not Mapped")) -> Kantha Kumar | E16: 999 | G16: 8 | H16: 2 | I16: 1009 | J16: 0 | K16: 1009
B17: BLR-Malagala | C17: =IF(B17="","",IFERROR(INDEX('CLM & IM Mapping'!$B$2:$B$270,MATCH(TRIM(B17),'CLM & IM Mapping'!$A$2:$A$270,0)),"Not Mapped")) -> Narasimhamurthy R | D17: =IF(B17="","",IFERROR(INDEX('CLM & IM Mapping'!$C$2:$C$270,MATCH(TRIM(B17),'CLM & IM Mapping'!$A$2:$A$270,0)),"Not Mapped")) -> Kishor K | E17: 997 | I17: 997 | J17: 0 | K17: 997
B18: BLR-Narayanapura | C18: =IF(B18="","",IFERROR(INDEX('CLM & IM Mapping'!$B$2:$B$270,MATCH(TRIM(B18),'CLM & IM Mapping'!$A$2:$A$270,0)),"Not Mapped")) -> Adhavan Subramani | D18: =IF(B18="","",IFERROR(INDEX('CLM & IM Mapping'!$C$2:$C$270,MATCH(TRIM(B18),'CLM & IM Mapping'!$A$2:$A$270,0)),"Not Mapped")) -> Mohammed Akbar | E18: 993 | I18: 993 | J18: 0 | K18: 993
B19: BLR-BTM-3 | C19: =IF(B19="","",IFERROR(INDEX('CLM & IM Mapping'!$B$2:$B$270,MATCH(TRIM(B19),'CLM & IM Mapping'!$A$2:$A$270,0)),"Not Mapped")) -> Raghavendra Vernekar | D19: =IF(B19="","",IFERROR(INDEX('CLM & IM Mapping'!$C$2:$C$270,MATCH(TRIM(B19),'CLM & IM Mapping'!$A$2:$A$270,0)),"Not Mapped")) -> Prakash BS | E19: 876 | G19: 16 | I19: 875 | J19: 17 | K19: 892
