Workbook

Sheet Shrinkage
A1: Zone | B1: city_name_ | C1: Store Name | D1: CLM | E1: IM | F1: locationtype2 | G1: Adj_Amt | H1: FCC_Bin_Amt | I1: Other_Bin_Amt | J1: Shortpick_Amt | K1: RTO_Loss | L1: PP PO Closed (curr+prev) | M1: PP STO Closed (curr+prev) | N1: PP Canc Closed (curr+prev) | O1: Total Inhouse | P1: SLP Ticket ID / Mail | Q1: SLP Recovery | R1: RCA & POA | S1: Expected Recovery by 11th Oct | T1: Top 2 Net Loss Aisle | U1: Top 2 Aisle Net Loss Value
A2: South1 | B2: Bengaluru | C2: BLR-Shivaji Nagar SS | D2: {=IF(C2="","",IFERROR(INDEX('CLM & IM Mapping'!$B$2:$B$270,MATCH(TRIM(C2),'CLM & IM Mapping'!$A$2:$A$270,0)),"Not Mapped"))} -> Arun Raj | E2: {=IF(C2="","",IFERROR(INDEX('CLM & IM Mapping'!$C$2:$C$270,MATCH(TRIM(C2),'CLM & IM Mapping'!$A$2:$A$270,0)),"Not Mapped"))} -> Simon Manoharan | F2: SUPERSTORE | G2: 69321 | H2: 75628 | I2: 0 | J2: 246 | K2: 1427 | L2: 0 | M2: 0 | N2: 9015 | O2: 155636 | T2: =IF($C2="","",IFERROR(INDEX('Aisle Loss Data'!$B$2:$B$1931,MATCH(TRIM($C2)&"|1",'Aisle Loss Data'!$E$2:$E$1931,0)),"No Loss")&IFERROR(","&INDEX('Aisle Loss Data'!$B$2:$B$1931,MATCH(TRIM($C2)&"|2",'Aisle Loss Data'!$E$2:$E$1931,0)),"")) -> P,J | U2: =IF($C2="","",IFERROR(INDEX('Aisle Loss Data'!$C$2:$C$1931,MATCH(TRIM($C2)&"|1",'Aisle Loss Data'!$E$2:$E$1931,0)),0)+IFERROR(INDEX('Aisle Loss Data'!$C$2:$C$1931,MATCH(TRIM($C2)&"|2",'Aisle Loss Data'!$E$2:$E$1931,0)),0)) -> 36993.74
A3: South1 | B3: Bengaluru | C3: BLR-RICHMOND TOWN SS | D3: {=IF(C3="","",IFERROR(INDEX('CLM & IM Mapping'!$B$2:$B$270,MATCH(TRIM(C3),'CLM & IM Mapping'!$A$2:$A$270,0)),"Not Mapped"))} -> Arun Raj | E3: {=IF(C3="","",IFERROR(INDEX('CLM & IM Mapping'!$C$2:$C$270,MATCH(TRIM(C3),'CLM & IM Mapping'!$A$2:$A$270,0)),"Not Mapped"))} -> Simon Manoharan | F3: SUPERSTORE | G3: 18075 | H3: 115931 | I3: -13909 | J3: 463 | K3: 14666 | L3: 0 | M3: 0 | N3: 0 | O3: 135225 | T3: =IF($C3="","",IFERROR(INDEX('Aisle Loss Data'!$B$2:$B$1931,MATCH(TRIM($C3)&"|1",'Aisle Loss Data'!$E$2:$E$1931,0)),"No Loss")&IFERROR(","&INDEX('Aisle Loss Data'!$B$2:$B$1931,MATCH(TRIM($C3)&"|2",'Aisle Loss Data'!$E$2:$E$1931,0)),"")) -> I,A | U3: =IF($C3="","",IFERROR(INDEX('Aisle Loss Data'!$C$2:$C$1931,MATCH(TRIM($C3)&"|1",'Aisle Loss Data'!$E$2:$E$1931,0)),0)+IFERROR(INDEX('Aisle Loss Data'!$C$2:$C$1931,MATCH(TRIM($C3)&"|2",'Aisle Loss Data'!$E$2:$E$1931,0)),0)) -> 48267.52
A4: South1 | B4: Bengaluru | C4: BLR-Mathikere | D4: {=IF(C4="","",IFERROR(INDEX('CLM & IM Mapping'!$B$2:$B$270,MATCH(TRIM(C4),'CLM & IM Mapping'!$A$2:$A$270,0)),"Not Mapped"))} -> Manoj Kj | E4: {=IF(C4="","",IFERROR(INDEX('CLM & IM Mapping'!$C$2:$C$270,MATCH(TRIM(C4),'CLM & IM Mapping'!$A$2:$A$270,0)),"Not Mapped"))} -> Srittam Dhal | F4: RETAIL_STORE | G4: -82711 | H4: 0 | I4: 0 | J4: 191944 | K4: 0 | L4: 0 | M4: 0 | N4: 1470 | O4: 110703 | T4: =IF($C4="","",IFERROR(INDEX('Aisle Loss Data'!$B$2:$B$1931,MATCH(TRIM($C4)&"|1",'Aisle Loss Data'!$E$2:$E$1931,0)),"No Loss")&IFERROR(","&INDEX('Aisle Loss Data'!$B$2:$B$1931,MATCH(TRIM($C4)&"|2",'Aisle Loss Data'!$E$2:$E$1931,0)),"")) -> K | U4: =IF($C4="","",IFERROR(INDEX('Aisle Loss Data'!$C$2:$C$1931,MATCH(TRIM($C4)&"|1",'Aisle Loss Data'!$E$2:$E$1931,0)),0)+IFERROR(INDEX('Aisle Loss Data'!$C$2:$C$1931,MATCH(TRIM($C4)&"|2",'Aisle Loss Data'!$E$2:$E$1931,0)),0)) -> 35.09
A5: South1 | B5: Bengaluru | C5: BLR-SHIVAJI NAGAR Network | D5: {=IF(C5="","",IFERROR(INDEX('CLM & IM Mapping'!$B$2:$B$270,MATCH(TRIM(C5),'CLM & IM Mapping'!$A$2:$A$270,0)),"Not Mapped"))} -> Vijay M | E5: {=IF(C5="","",IFERROR(INDEX('CLM & IM Mapping'!$C$2:$C$270,MATCH(TRIM(C5),'CLM & IM Mapping'!$A$2:$A$270,0)),"Not Mapped"))} -> Kantha Kumar | F5: RETAIL_STORE | G5: 39978 | H5: 61074 | I5: 219 | J5: 451 | K5: 1542 | L5: 0 | M5: 1737 | N5: 0 | O5: 105001 | P5: Wrong putaway on Last month and theft involvement SLP Team investigation under process | T5: =IF($C5="","",IFERROR(INDEX('Aisle Loss Data'!$B$2:$B$1931,MATCH(TRIM($C5)&"|1",'Aisle Loss Data'!$E$2:$E$1931,0)),"No Loss")&IFERROR(","&INDEX('Aisle Loss Data'!$B$2:$B$1931,MATCH(TRIM($C5)&"|2",'Aisle Loss Data'!$E$2:$E$1931,0)),"")) -> A,B | U5: =IF($C5="","",IFERROR(INDEX('Aisle Loss Data'!$C$2:$C$1931,MATCH(TRIM($C5)&"|1",'Aisle Loss Data'!$E$2:$E$1931,0)),0)+IFERROR(INDEX('Aisle Loss Data'!$C$2:$C$1931,MATCH(TRIM($C5)&"|2",'Aisle Loss Data'!$E$2:$E$1931,0)),0)) -> 45815.7
A6: South1 | B6: Bengaluru | C6: BLR-Dooravani Nagar | D6: {=IF(C6="","",IFERROR(INDEX('CLM & IM Mapping'!$B$2:$B$270,MATCH(TRIM(C6),'CLM & IM Mapping'!$A$2:$A$270,0)),"Not Mapped"))} -> Rizwan Ahmed | E6: {=IF(C6="","",IFERROR(INDEX('CLM & IM Mapping'!$C$2:$C$270,MATCH(TRIM(C6),'CLM & IM Mapping'!$A$2:$A$270,0)),"Not Mapped"))} -> Un Mapped | F6: RETAIL_STORE | G6: 22334 | H6: 66087 | I6: 0 | J6: 731 | K6: 763 | L6: 0 | M6: 4541 | N6: 0 | O6: 94456 | T6: =IF($C6="","",IFERROR(INDEX('Aisle Loss Data'!$B$2:$B$1931,MATCH(TRIM($C6)&"|1",'Aisle Loss Data'!$E$2:$E$1931,0)),"No Loss")&IFERROR(","&INDEX('Aisle Loss Data'!$B$2:$B$1931,MATCH(TRIM($C6)&"|2",'Aisle Loss Data'!$E$2:$E$1931,0)),"")) -> A,E | U6: =IF($C6="","",IFERROR(INDEX('Aisle Loss Data'!$C$2:$C$1931,MATCH(TRIM($C6)&"|1",'Aisle Loss Data'!$E$2:$E$1931,0)),0)+IFERROR(INDEX('Aisle Loss Data'!$C$2:$C$1931,MATCH(TRIM($C6)&"|2",'Aisle Loss Data'!$E$2:$E$1931,0)),0)) -> 61440.43
A7: South1 | B7: Bengaluru | C7: BLR-Kalkere | D7: {=IF(C7="","",IFERROR(INDEX('CLM & IM Mapping'!$B$2:$B$270,MATCH(TRIM(C7),'CLM & IM Mapping'!$A$2:$A$270,0)),"Not Mapped"))} -> Rizwan Ahmed | E7: {=IF(C7="","",IFERROR(INDEX('CLM & IM Mapping'!$C$2:$C$270,MATCH(TRIM(C7),'CLM & IM Mapping'!$A$2:$A$270,0)),"Not Mapped"))} -> Un Mapped | F7: RETAIL_STORE | G7: 71595 | H7: 9181 | I7: 0 | J7: 360 | K7: 87 | L7: 0 | M7: 1957 | N7: 0 | O7: 83180 | T7: =IF($C7="","",IFERROR(INDEX('Aisle Loss Data'!$B$2:$B$1931,MATCH(TRIM($C7)&"|1",'Aisle Loss Data'!$E$2:$E$1931,0)),"No Loss")&IFERROR(","&INDEX('Aisle Loss Data'!$B$2:$B$1931,MATCH(TRIM($C7)&"|2",'Aisle Loss Data'!$E$2:$E$1931,0)),"")) -> I,C | U7: =IF($C7="","",IFERROR(INDEX('Aisle Loss Data'!$C$2:$C$1931,MATCH(TRIM($C7)&"|1",'Aisle Loss Data'!$E$2:$E$1931,0)),0)+IFERROR(INDEX('Aisle Loss Data'!$C$2:$C$1931,MATCH(TRIM($C7)&"|2",'Aisle Loss Data'!$E$2:$E$1931,0)),0)) -> 16676.04
A8: South1 | B8: Bengaluru | C8: BLR-HSR-3 | D8: {=IF(C8="","",IFERROR(INDEX('CLM & IM Mapping'!$B$2:$B$270,MATCH(TRIM(C8),'CLM & IM Mapping'!$A$2:$A$270,0)),"Not Mapped"))} -> Saddam Hussain | E8: {=IF(C8="","",IFERROR(INDEX('CLM & IM Mapping'!$C$2:$C$270,MATCH(TRIM(C8),'CLM & IM Mapping'!$A$2:$A$270,0)),"Not Mapped"))} -> Un Mapped | F8: RETAIL_STORE | G8: 15940 | H8: 42998 | I8: 1688 | J8: 2605 | K8: 3932 | L8: 0 | M8: 680 | N8: 0 | O8: 67844 | T8: =IF($C8="","",IFERROR(INDEX('Aisle Loss Data'!$B$2:$B$1931,MATCH(TRIM($C8)&"|1",'Aisle Loss Data'!$E$2:$E$1931,0)),"No Loss")&IFERROR(","&INDEX('Aisle Loss Data'!$B$2:$B$1931,MATCH(TRIM($C8)&"|2",'Aisle Loss Data'!$E$2:$E$1931,0)),"")) -> A,I | U8: =IF($C8="","",IFERROR(INDEX('Aisle Loss Data'!$C$2:$C$1931,MATCH(TRIM($C8)&"|1",'Aisle Loss Data'!$E$2:$E$1931,0)),0)+IFERROR(INDEX('Aisle Loss Data'!$C$2:$C$1931,MATCH(TRIM($C8)&"|2",'Aisle Loss Data'!$E$2:$E$1931,0)),0)) -> 41543.29
A9: South1 | B9: Bengaluru | C9: BLR-Malleshwaram SS | D9: {=IF(C9="","",IFERROR(INDEX('CLM & IM Mapping'!$B$2:$B$270,MATCH(TRIM(C9),'CLM & IM Mapping'!$A$2:$A$270,0)),"Not Mapped"))} -> Arun Raj | E9: {=IF(C9="","",IFERROR(INDEX('CLM & IM Mapping'!$C$2:$C$270,MATCH(TRIM(C9),'CLM & IM Mapping'!$A$2:$A$270,0)),"Not Mapped"))} -> Simon Manoharan | F9: SUPERSTORE | G9: 19452 | H9: 38867 | I9: 0 | J9: 0 | K9: 530 | L9: 0 | M9: 37 | N9: 0 | O9: 58886 | T9: =IF($C9="","",IFERROR(INDEX('Aisle Loss Data'!$B$2:$B$1931,MATCH(TRIM($C9)&"|1",'Aisle Loss Data'!$E$2:$E$1931,0)),"No Loss")&IFERROR(","&INDEX('Aisle Loss Data'!$B$2:$B$1931,MATCH(TRIM($C9)&"|2",'Aisle Loss Data'!$E$2:$E$1931,0)),"")) -> I,G | U9: =IF($C9="","",IFERROR(INDEX('Aisle Loss Data'!$C$2:$C$1931,MATCH(TRIM($C9)&"|1",'Aisle Loss Data'!$E$2:$E$1931,0)),0)+IFERROR(INDEX('Aisle Loss Data'!$C$2:$C$1931,MATCH(TRIM($C9)&"|2",'Aisle Loss Data'!$E$2:$E$1931,0)),0)) -> 18584.25
A10: South1 | B10: Bengaluru | C10: BLR-BASAVANAPURA NETWORK 2 | D10: {=IF(C10="","",IFERROR(INDEX('CLM & IM Mapping'!$B$2:$B$270,MATCH(TRIM(C10),'CLM & IM Mapping'!$A$2:$A$270,0)),"Not Mapped"))} -> Richard Harris | E10: {=IF(C10="","",IFERROR(INDEX('CLM & IM Mapping'!$C$2:$C$270,MATCH(TRIM(C10),'CLM & IM Mapping'!$A$2:$A$270,0)),"Not Mapped"))} -> Kantha Kumar | F10: RETAIL_STORE | G10: 41355 | H10: 12847 | I10: 226 | J10: 2374 | K10: 948 | L10: 0 | M10: 0 | N10: 0 | O10: 57750 | T10: =IF($C10="","",IFERROR(INDEX('Aisle Loss Data'!$B$2:$B$1931,MATCH(TRIM($C10)&"|1",'Aisle Loss Data'!$E$2:$E$1931,0)),"No Loss")&IFERROR(","&INDEX('Aisle Loss Data'!$B$2:$B$1931,MATCH(TRIM($C10)&"|2",'Aisle Loss Data'!$E$2:$E$1931,0)),"")) -> K,A | U10: =IF($C10="","",IFERROR(INDEX('Aisle Loss Data'!$C$2:$C$1931,MATCH(TRIM($C10)&"|1",'Aisle Loss Data'!$E$2:$E$1931,0)),0)+IFERROR(INDEX('Aisle Loss Data'!$C$2:$C$1931,MATCH(TRIM($C10)&"|2",'Aisle Loss Data'!$E$2:$E$1931,0)),0)) -> 31906.19
A11: South1 | B11: Bengaluru | C11: BLR-Mico layout New | D11: {=IF(C11="","",IFERROR(INDEX('CLM & IM Mapping'!$B$2:$B$270,MATCH(TRIM(C11),'CLM & IM Mapping'!$A$2:$A$270,0)),"Not Mapped"))} -> Keshav G | E11: {=IF(C11="","",IFERROR(INDEX('CLM & IM Mapping'!$C$2:$C$270,MATCH(TRIM(C11),'CLM & IM Mapping'!$A$2:$A$270,0)),"Not Mapped"))} -> Un Mapped | F11: RETAIL_STORE | G11: 5817 | H11: 29841 | I11: 0 | J11: 1403 | K11: 3816 | L11: 0 | M11: 0 | N11: 13273 | O11: 54150 | T11: =IF($C11="","",IFERROR(INDEX('Aisle Loss Data'!$B$2:$B$1931,MATCH(TRIM($C11)&"|1",'Aisle Loss Data'!$E$2:$E$1931,0)),"No Loss")&IFERROR(","&INDEX('Aisle Loss Data'!$B$2:$B$1931,MATCH(TRIM($C11)&"|2",'Aisle Loss Data'!$E$2:$E$1931,0)),"")) -> J,A | U11: =IF($C11="","",IFERROR(INDEX('Aisle Loss Data'!$C$2:$C$1931,MATCH(TRIM($C11)&"|1",'Aisle Loss Data'!$E$2:$E$1931,0)),0)+IFERROR(INDEX('Aisle Loss Data'!$C$2:$C$1931,MATCH(TRIM($C11)&"|2",'Aisle Loss Data'!$E$2:$E$1931,0)),0)) -> 23909.33
A12: South1 | B12: Bengaluru | C12: BLR-HSR Layout New | D12: {=IF(C12="","",IFERROR(INDEX('CLM & IM Mapping'!$B$2:$B$270,MATCH(TRIM(C12),'CLM & IM Mapping'!$A$2:$A$270,0)),"Not Mapped"))} -> Saddam Hussain | E12: {=IF(C12="","",IFERROR(INDEX('CLM & IM Mapping'!$C$2:$C$270,MATCH(TRIM(C12),'CLM & IM Mapping'!$A$2:$A$270,0)),"Not Mapped"))} -> Un Mapped | F12: RETAIL_STORE | G12: 20452 | H12: 23732 | I12: 0 | J12: 7696 | K12: 584 | L12: 0 | M12: 1629 | N12: 0 | O12: 54093 | T12: =IF($C12="","",IFERROR(INDEX('Aisle Loss Data'!$B$2:$B$1931,MATCH(TRIM($C12)&"|1",'Aisle Loss Data'!$E$2:$E$1931,0)),"No Loss")&IFERROR(","&INDEX('Aisle Loss Data'!$B$2:$B$1931,MATCH(TRIM($C12)&"|2",'Aisle Loss Data'!$E$2:$E$1931,0)),"")) -> J,K | U12: =IF($C12="","",IFERROR(INDEX('Aisle Loss Data'!$C$2:$C$1931,MATCH(TRIM($C12)&"|1",'Aisle Loss Data'!$E$2:$E$1931,0)),0)+IFERROR(INDEX('Aisle Loss Data'!$C$2:$C$1931,MATCH(TRIM($C12)&"|2",'Aisle Loss Data'!$E$2:$E$1931,0)),0)) -> 17533.08
A13: South1 | B13: Bengaluru | C13: BLR-Siddapura | D13: {=IF(C13="","",IFERROR(INDEX('CLM & IM Mapping'!$B$2:$B$270,MATCH(TRIM(C13),'CLM & IM Mapping'!$A$2:$A$270,0)),"Not Mapped"))} -> Basil Scariya | E13: {=IF(C13="","",IFERROR(INDEX('CLM & IM Mapping'!$C$2:$C$270,MATCH(TRIM(C13),'CLM & IM Mapping'!$A$2:$A$270,0)),"Not Mapped"))} -> Prakash BS | F13: RETAIL_STORE | G13: 37013 | H13: 13720 | I13: 0 | J13: 0 | K13: 69 | L13: 0 | M13: 1350 | N13: 0 | O13: 52152 | T13: =IF($C13="","",IFERROR(INDEX('Aisle Loss Data'!$B$2:$B$1931,MATCH(TRIM($C13)&"|1",'Aisle Loss Data'!$E$2:$E$1931,0)),"No Loss")&IFERROR(","&INDEX('Aisle Loss Data'!$B$2:$B$1931,MATCH(TRIM($C13)&"|2",'Aisle Loss Data'!$E$2:$E$1931,0)),"")) -> D,C | U13: =IF($C13="","",IFERROR(INDEX('Aisle Loss Data'!$C$2:$C$1931,MATCH(TRIM($C13)&"|1",'Aisle Loss Data'!$E$2:$E$1931,0)),0)+IFERROR(INDEX('Aisle Loss Data'!$C$2:$C$1931,MATCH(TRIM($C13)&"|2",'Aisle Loss Data'!$E$2:$E$1931,0)),0)) -> 36338.63
A14: South1 | B14: Bengaluru | C14: BLR-Narayanapura | D14: {=IF(C14="","",IFERROR(INDEX('CLM & IM Mapping'!$B$2:$B$270,MATCH(TRIM(C14),'CLM & IM Mapping'!$A$2:$A$270,0)),"Not Mapped"))} -> Adhavan Subramani | E14: {=IF(C14="","",IFERROR(INDEX('CLM & IM Mapping'!$C$2:$C$270,MATCH(TRIM(C14),'CLM & IM Mapping'!$A$2:$A$270,0)),"Not Mapped"))} -> Mohammed Akbar | F14: RETAIL_STORE | G14: 16761 | H14: 27598 | I14: 0 | J14: 5808 | K14: 1603 | L14: 0 | M14: 0 | N14: 0 | O14: 51771 | T14: =IF($C14="","",IFERROR(INDEX('Aisle Loss Data'!$B$2:$B$1931,MATCH(TRIM($C14)&"|1",'Aisle Loss Data'!$E$2:$E$1931,0)),"No Loss")&IFERROR(","&INDEX('Aisle Loss Data'!$B$2:$B$1931,MATCH(TRIM($C14)&"|2",'Aisle Loss Data'!$E$2:$E$1931,0)),"")) -> I,J | U14: =IF($C14="","",IFERROR(INDEX('Aisle Loss Data'!$C$2:$C$1931,MATCH(TRIM($C14)&"|1",'Aisle Loss Data'!$E$2:$E$1931,0)),0)+IFERROR(INDEX('Aisle Loss Data'!$C$2:$C$1931,MATCH(TRIM($C14)&"|2",'Aisle Loss Data'!$E$2:$E$1931,0)),0)) -> 28905.72
A15: South1 | B15: Bengaluru | C15: BLR-Challakere | D15: {=IF(C15="","",IFERROR(INDEX('CLM & IM Mapping'!$B$2:$B$270,MATCH(TRIM(C15),'CLM & IM Mapping'!$A$2:$A$270,0)),"Not Mapped"))} -> Girish N | E15: {=IF(C15="","",IFERROR(INDEX('CLM & IM Mapping'!$C$2:$C$270,MATCH(TRIM(C15),'CLM & IM Mapping'!$A$2:$A$270,0)),"Not Mapped"))} -> Un Mapped | F15: RETAIL_STORE | G15: 34189 | H15: 13467 | I15: 1279 | J15: 0 | K15: 541 | L15: 0 | M15: 21 | N15: 0 | O15: 49497 | T15: =IF($C15="","",IFERROR(INDEX('Aisle Loss Data'!$B$2:$B$1931,MATCH(TRIM($C15)&"|1",'Aisle Loss Data'!$E$2:$E$1931,0)),"No Loss")&IFERROR(","&INDEX('Aisle Loss Data'!$B$2:$B$1931,MATCH(TRIM($C15)&"|2",'Aisle Loss Data'!$E$2:$E$1931,0)),"")) -> J,K | U15: =IF($C15="","",IFERROR(INDEX('Aisle Loss Data'!$C$2:$C$1931,MATCH(TRIM($C15)&"|1",'Aisle Loss Data'!$E$2:$E$1931,0)),0)+IFERROR(INDEX('Aisle Loss Data'!$C$2:$C$1931,MATCH(TRIM($C15)&"|2",'Aisle Loss Data'!$E$2:$E$1931,0)),0)) -> 20481.68
A16: South1 | B16: Bengaluru | C16: BLR-Banjara Layout | D16: {=IF(C16="","",IFERROR(INDEX('CLM & IM Mapping'!$B$2:$B$270,MATCH(TRIM(C16),'CLM & IM Mapping'!$A$2:$A$270,0)),"Not Mapped"))} -> Rizwan Ahmed | E16: {=IF(C16="","",IFERROR(INDEX('CLM & IM Mapping'!$C$2:$C$270,MATCH(TRIM(C16),'CLM & IM Mapping'!$A$2:$A$270,0)),"Not Mapped"))} -> Un Mapped | F16: RETAIL_STORE | G16: 31101 | H16: 16912 | I16: 235 | J16: 28 | K16: 595 | L16: 0 | M16: 0 | N16: 0 | O16: 48871 | T16: =IF($C16="","",IFERROR(INDEX('Aisle Loss Data'!$B$2:$B$1931,MATCH(TRIM($C16)&"|1",'Aisle Loss Data'!$E$2:$E$1931,0)),"No Loss")&IFERROR(","&INDEX('Aisle Loss Data'!$B$2:$B$1931,MATCH(TRIM($C16)&"|2",'Aisle Loss Data'!$E$2:$E$1931,0)),"")) -> L,P | U16: =IF($C16="","",IFERROR(INDEX('Aisle Loss Data'!$C$2:$C$1931,MATCH(TRIM($C16)&"|1",'Aisle Loss Data'!$E$2:$E$1931,0)),0)+IFERROR(INDEX('Aisle Loss Data'!$C$2:$C$1931,MATCH(TRIM($C16)&"|2",'Aisle Loss Data'!$E$2:$E$1931,0)),0)) -> 11017.72
A17: South1 | B17: Bengaluru | C17: BLR-Vijay Nagar Network | D17: {=IF(C17="","",IFERROR(INDEX('CLM & IM Mapping'!$B$2:$B$270,MATCH(TRIM(C17),'CLM & IM Mapping'!$A$2:$A$270,0)),"Not Mapped"))} -> Narasimhamurthy R | E17: {=IF(C17="","",IFERROR(INDEX('CLM & IM Mapping'!$C$2:$C$270,MATCH(TRIM(C17),'CLM & IM Mapping'!$A$2:$A$270,0)),"Not Mapped"))} -> Kishor K | F17: RETAIL_STORE | G17: 26779 | H17: 20348 | I17: 0 | J17: 1436 | K17: 101 | L17: 0 | M17: 0 | N17: 0 | O17: 48665 | R17: Due to CCA delta & Peak CCA not abelt at add exxcess | S17: Complete losses will be recovered (50K) | T17: =IF($C17="","",IFERROR(INDEX('Aisle Loss Data'!$B$2:$B$1931,MATCH(TRIM($C17)&"|1",'Aisle Loss Data'!$E$2:$E$1931,0)),"No Loss")&IFERROR(","&INDEX('Aisle Loss Data'!$B$2:$B$1931,MATCH(TRIM($C17)&"|2",'Aisle Loss Data'!$E$2:$E$1931,0)),"")) -> A,G | U17: =IF($C17="","",IFERROR(INDEX('Aisle Loss Data'!$C$2:$C$1931,MATCH(TRIM($C17)&"|1",'Aisle Loss Data'!$E$2:$E$1931,0)),0)+IFERROR(INDEX('Aisle Loss Data'!$C$2:$C$1931,MATCH(TRIM($C17)&"|2",'Aisle Loss Data'!$E$2:$E$1931,0)),0)) -> 29309.65
A18: South1 | B18: Bengaluru | C18: BLR-Malleshpalya | D18: {=IF(C18="","",IFERROR(INDEX('CLM & IM Mapping'!$B$2:$B$270,MATCH(TRIM(C18),'CLM & IM Mapping'!$A$2:$A$270,0)),"Not Mapped"))} -> Silambarasan E | E18: {=IF(C18="","",IFERROR(INDEX('CLM & IM Mapping'!$C$2:$C$270,MATCH(TRIM(C18),'CLM & IM Mapping'!$A$2:$A$270,0)),"Not Mapped"))} -> Arivind S | F18: RETAIL_STORE | G18: 44009 | H18: 4060 | I18: 0 | J18: 0 | K18: 190 | L18: 0 | M18: 0 | N18: 0 | O18: 48259 | T18: =IF($C18="","",IFERROR(INDEX('Aisle Loss Data'!$B$2:$B$1931,MATCH(TRIM($C18)&"|1",'Aisle Loss Data'!$E$2:$E$1931,0)),"No Loss")&IFERROR(","&INDEX('Aisle Loss Data'!$B$2:$B$1931,MATCH(TRIM($C18)&"|2",'Aisle Loss Data'!$E$2:$E$1931,0)),"")) -> L,M | U18: =IF($C18="","",IFERROR(INDEX('Aisle Loss Data'!$C$2:$C$1931,MATCH(TRIM($C18)&"|1",'Aisle Loss Data'!$E$2:$E$1931,0)),0)+IFERROR(INDEX('Aisle Loss Data'!$C$2:$C$1931,MATCH(TRIM($C18)&"|2",'Aisle Loss Data'!$E$2:$E$1931,0)),0)) -> 15781.26
A19: South1 | B19: Bengaluru | C19: BLR-Doddakannelli | D19: {=IF(C19="","",IFERROR(INDEX('CLM & IM Mapping'!$B$2:$B$270,MATCH(TRIM(C19),'CLM & IM Mapping'!$A$2:$A$270,0)),"Not Mapped"))} -> Sundaresh S | E19: {=IF(C19="","",IFERROR(INDEX('CLM & IM Mapping'!$C$2:$C$270,MATCH(TRIM(C19),'CLM & IM Mapping'!$A$2:$A$270,0)),"Not Mapped"))} -> Un Mapped | F19: RETAIL_STORE | G19: 15241 | H19: 17511 | I19: 0 | J19: 651 | K19: 1730 | L19: 0 | M19: 12084 | N19: 0 | O19: 47218 | T19: =IF($C19="","",IFERROR(INDEX('Aisle Loss Data'!$B$2:$B$1931,MATCH(TRIM($C19)&"|1",'Aisle Loss Data'!$E$2:$E$1931,0)),"No Loss")&IFERROR(","&INDEX('Aisle Loss Data'!$B$2:$B$1931,MATCH(TRIM($C19)&"|2",'Aisle Loss Data'!$E$2:$E$1931,0)),"")) -> E,C | U19: =IF($C19="","",IFERROR(INDEX('Aisle Loss Data'!$C$2:$C$1931,MATCH(TRIM($C19)&"|1",'Aisle Loss Data'!$E$2:$E$1931,0)),0)+IFERROR(INDEX('Aisle Loss Data'!$C$2:$C$1931,MATCH(TRIM($C19)&"|2",'Aisle Loss Data'!$E$2:$E$1931,0)),0)) -> 21608.03
A20: South1 | B20: Bengaluru | C20: BLR-Murugeshpalya | D20: {=IF(C20="","",IFERROR(INDEX('CLM & IM Mapping'!$B$2:$B$270,MATCH(TRIM(C20),'CLM & IM Mapping'!$A$2:$A$270,0)),"Not Mapped"))} -> Keshav G | E20: {=IF(C20="","",IFERROR(INDEX('CLM & IM Mapping'!$C$2:$C$270,MATCH(TRIM(C20),'CLM & IM Mapping'!$A$2:$A$270,0)),"Not Mapped"))} -> Mohammed Akbar | F20: RETAIL_STORE | G20: 9409 | H20: 27235 | I20: 0 | J20: 235 | K20: 6731 | L20: 0 | M20: 3486 | N20: 0 | O20: 47094 | T20: =IF($C20="","",IFERROR(INDEX('Aisle Loss Data'!$B$2:$B$1931,MATCH(TRIM($C20)&"|1",'Aisle Loss Data'!$E$2:$E$1931,0)),"No Loss")&IFERROR(","&INDEX('Aisle Loss Data'!$B$2:$B$1931,MATCH(TRIM($C20)&"|2",'Aisle Loss Data'!$E$2:$E$1931,0)),"")) -> AI,G | U20: =IF($C20="","",IFERROR(INDEX('Aisle Loss Data'!$C$2:$C$1931,MATCH(TRIM($C20)&"|1",'Aisle Loss Data'!$E$2:$E$1931,0)),0)+IFERROR(INDEX('Aisle Loss Data'!$C$2:$C$1931,MATCH(TRIM($C20)&"|2",'Aisle Loss Data'!$E$2:$E$1931,0)),0)) -> 25002.2
A21: South1 | B21: Bengaluru | C21: BLR-Kudlu | D21: {=IF(C21="","",IFERROR(INDEX('CLM & IM Mapping'!$B$2:$B$270,MATCH(TRIM(C21),'CLM & IM Mapping'!$A$2:$A$270,0)),"Not Mapped"))} -> Raghavendra Vernekar | E21: {=IF(C21="","",IFERROR(INDEX('CLM & IM Mapping'!$C$2:$C$270,MATCH(TRIM(C21),'CLM & IM Mapping'!$A$2:$A$270,0)),"Not Mapped"))} -> Prakash BS | F21: RETAIL_STORE | G21: 27603 | H21: 14083 | I21: 0 | J21: 3884 | K21: 804 | L21: 0 | M21: 0 | N21: 0 | O21: 46374 | T21: =IF($C21="","",IFERROR(INDEX('Aisle Loss Data'!$B$2:$B$1931,MATCH(TRIM($C21)&"|1",'Aisle Loss Data'!$E$2:$E$1931,0)),"No Loss")&IFERROR(","&INDEX('Aisle Loss Data'!$B$2:$B$1931,MATCH(TRIM($C21)&"|2",'Aisle Loss Data'!$E$2:$E$1931,0)),"")) -> C,I | U21: =IF($C21="","",IFERROR(INDEX('Aisle Loss Data'!$C$2:$C$1931,MATCH(TRIM($C21)&"|1",'Aisle Loss Data'!$E$2:$E$1931,0)),0)+IFERROR(INDEX('Aisle Loss Data'!$C$2:$C$1931,MATCH(TRIM($C21)&"|2",'Aisle Loss Data'!$E$2:$E$1931,0)),0)) -> 31277.27
A22: South1 | B22: Bengaluru | C22: BLR-Bommanahalli | D22: {=IF(C22="","",IFERROR(INDEX('CLM & IM Mapping'!$B$2:$B$270,MATCH(TRIM(C22),'CLM & IM Mapping'!$A$2:$A$270,0)),"Not Mapped"))} -> Raghavendra Vernekar | E22: {=IF(C22="","",IFERROR(INDEX('CLM & IM Mapping'!$C$2:$C$270,MATCH(TRIM(C22),'CLM & IM Mapping'!$A$2:$A$270,0)),"Not Mapped"))} -> Prakash BS | F22: RETAIL_STORE | G22: 201 | H22: 2037 | I22: 0 | J22: 0 | K22: 170 | L22: 0 | M22: 41386 | N22: 0 | O22: 43795 | T22: =IF($C22="","",IFERROR(INDEX('Aisle Loss Data'!$B$2:$B$1931,MATCH(TRIM($C22)&"|1",'Aisle Loss Data'!$E$2:$E$1931,0)),"No Loss")&IFERROR(","&INDEX('Aisle Loss Data'!$B$2:$B$1931,MATCH(TRIM($C22)&"|2",'Aisle Loss Data'!$E$2:$E$1931,0)),"")) -> R,Q | U22: =IF($C22="","",IFERROR(INDEX('Aisle Loss Data'!$C$2:$C$1931,MATCH(TRIM($C22)&"|1",'Aisle Loss Data'!$E$2:$E$1931,0)),0)+IFERROR(INDEX('Aisle Loss Data'!$C$2:$C$1931,MATCH(TRIM($C22)&"|2",'Aisle Loss Data'!$E$2:$E$1931,0)),0)) -> 4747.3
A23: South1 | B23: Bengaluru | C23: BLR-Electronic city network | D23: {=IF(C23="","",IFERROR(INDEX('CLM & IM Mapping'!$B$2:$B$270,MATCH(TRIM(C23),'CLM & IM Mapping'!$A$2:$A$270,0)),"Not Mapped"))} -> Balaji G | E23: {=IF(C23="","",IFERROR(INDEX('CLM & IM Mapping'!$C$2:$C$270,MATCH(TRIM(C23),'CLM & IM Mapping'!$A$2:$A$270,0)),"Not Mapped"))} -> Mohammed Akbar | F23: RETAIL_STORE | G23: 3171 | H23: 31819 | I23: 2882 | J23: 3955 | K23: 1745 | L23: 0 | M23: 0 | N23: 0 | O23: 43571 | T23: =IF($C23="","",IFERROR(INDEX('Aisle Loss Data'!$B$2:$B$1931,MATCH(TRIM($C23)&"|1",'Aisle Loss Data'!$E$2:$E$1931,0)),"No Loss")&IFERROR(","&INDEX('Aisle Loss Data'!$B$2:$B$1931,MATCH(TRIM($C23)&"|2",'Aisle Loss Data'!$E$2:$E$1931,0)),"")) -> I,J | U23: =IF($C23="","",IFERROR(INDEX('Aisle Loss Data'!$C$2:$C$1931,MATCH(TRIM($C23)&"|1",'Aisle Loss Data'!$E$2:$E$1931,0)),0)+IFERROR(INDEX('Aisle Loss Data'!$C$2:$C$1931,MATCH(TRIM($C23)&"|2",'Aisle Loss Data'!$E$2:$E$1931,0)),0)) -> 31809.63
A24: South1 | B24: Bengaluru | C24: BLR-Sattava East | D24: {=IF(C24="","",IFERROR(INDEX('CLM & IM Mapping'!$B$2:$B$270,MATCH(TRIM(C24),'CLM & IM Mapping'!$A$2:$A$270,0)),"Not Mapped"))} -> Ashwath S | E24: {=IF(C24="","",IFERROR(INDEX('CLM & IM Mapping'!$C$2:$C$270,MATCH(TRIM(C24),'CLM & IM Mapping'!$A$2:$A$270,0)),"Not Mapped"))} -> Kantha Kumar | F24: RETAIL_STORE | G24: 33628 | H24: 9141 | I24: 0 | J24: 0 | K24: 243 | L24: 0 | M24: 0 | N24: 0 | O24: 43012 | T24: =IF($C24="","",IFERROR(INDEX('Aisle Loss Data'!$B$2:$B$1931,MATCH(TRIM($C24)&"|1",'Aisle Loss Data'!$E$2:$E$1931,0)),"No Loss")&IFERROR(","&INDEX('Aisle Loss Data'!$B$2:$B$1931,MATCH(TRIM($C24)&"|2",'Aisle Loss Data'!$E$2:$E$1931,0)),"")) -> H,B | U24: =IF($C24="","",IFERROR(INDEX('Aisle Loss Data'!$C$2:$C$1931,MATCH(TRIM($C24)&"|1",'Aisle Loss Data'!$E$2:$E$1931,0)),0)+IFERROR(INDEX('Aisle Loss Data'!$C$2:$C$1931,MATCH(TRIM($C24)&"|2",'Aisle Loss Data'!$E$2:$E$1931,0)),0)) -> 20792.5
A25: South1 | B25: Bengaluru | C25: BLR-Kadarenahalli | D25: {=IF(C25="","",IFERROR(INDEX('CLM & IM Mapping'!$B$2:$B$270,MATCH(TRIM(C25),'CLM & IM Mapping'!$A$2:$A$270,0)),"Not Mapped"))} -> Raghavendra Vernekar | E25: {=IF(C25="","",IFERROR(INDEX('CLM & IM Mapping'!$C$2:$C$270,MATCH(TRIM(C25),'CLM & IM Mapping'!$A$2:$A$270,0)),"Not Mapped"))} -> Prakash BS | F25: RETAIL_STORE | G25: -18636 | H25: 26089 | I25: 0 | J25: 228 | K25: 237 | L25: 0 | M25: 2148 | N25: 32886 | O25: 42952 | T25: =IF($C25="","",IFERROR(INDEX('Aisle Loss Data'!$B$2:$B$1931,MATCH(TRIM($C25)&"|1",'Aisle Loss Data'!$E$2:$E$1931,0)),"No Loss")&IFERROR(","&INDEX('Aisle Loss Data'!$B$2:$B$1931,MATCH(TRIM($C25)&"|2",'Aisle Loss Data'!$E$2:$E$1931,0)),"")) -> C,H | U25: =IF($C25="","",IFERROR(INDEX('Aisle Loss Data'!$C$2:$C$1931,MATCH(TRIM($C25)&"|1",'Aisle Loss Data'!$E$2:$E$1931,0)),0)+IFERROR(INDEX('Aisle Loss Data'!$C$2:$C$1931,MATCH(TRIM($C25)&"|2",'Aisle Loss Data'!$E$2:$E$1931,0)),0)) -> 17465.43
A26: South1 | B26: Bengaluru | C26: BLR-Marathahalli-3 | D26: {=IF(C26="","",IFERROR(INDEX('CLM & IM Mapping'!$B$2:$B$270,MATCH(TRIM(C26),'CLM & IM Mapping'!$A$2:$A$270,0)),"Not Mapped"))} -> Sundaresh S | E26: {=IF(C26="","",IFERROR(INDEX('CLM & IM Mapping'!$C$2:$C$270,MATCH(TRIM(C26),'CLM & IM Mapping'!$A$2:$A$270,0)),"Not Mapped"))} -> Un Mapped | F26: RETAIL_STORE | G26: 23680 | H26: 12580 | I26: 38 | J26: 5740 | K26: 746 | L26: 0 | M26: 0 | N26: 0 | O26: 42783 | T26: =IF($C26="","",IFERROR(INDEX('Aisle Loss Data'!$B$2:$B$1931,MATCH(TRIM($C26)&"|1",'Aisle Loss Data'!$E$2:$E$1931,0)),"No Loss")&IFERROR(","&INDEX('Aisle Loss Data'!$B$2:$B$1931,MATCH(TRIM($C26)&"|2",'Aisle Loss Data'!$E$2:$E$1931,0)),"")) -> H,C | U26: =IF($C26="","",IFERROR(INDEX('Aisle Loss Data'!$C$2:$C$1931,MATCH(TRIM($C26)&"|1",'Aisle Loss Data'!$E$2:$E$1931,0)),0)+IFERROR(INDEX('Aisle Loss Data'!$C$2:$C$1931,MATCH(TRIM($C26)&"|2",'Aisle Loss Data'!$E$2:$E$1931,0)),0)) -> 36505.89
A27: South1 | B27: Bengaluru | C27: BLR-Jakkur Network | D27: {=IF(C27="","",IFERROR(INDEX('CLM & IM Mapping'!$B$2:$B$270,MATCH(TRIM(C27),'CLM & IM Mapping'!$A$2:$A$270,0)),"Not Mapped"))} -> Girish N | E27: {=IF(C27="","",IFERROR(INDEX('CLM & IM Mapping'!$C$2:$C$270,MATCH(TRIM(C27),'CLM & IM Mapping'!$A$2:$A$270,0)),"Not Mapped"))} -> Un Mapped | F27: RETAIL_STORE | G27: 29680 | H27: 9315 | I27: 0 | J27: 3498 | K27: 283 | L27: 0 | M27: 0 | N27: 0 | O27: 42776 | T27: =IF($C27="","",IFERROR(INDEX('Aisle Loss Data'!$B$2:$B$1931,MATCH(TRIM($C27)&"|1",'Aisle Loss Data'!$E$2:$E$1931,0)),"No Loss")&IFERROR(","&INDEX('Aisle Loss Data'!$B$2:$B$1931,MATCH(TRIM($C27)&"|2",'Aisle Loss Data'!$E$2:$E$1931,0)),"")) -> A,B | U27: =IF($C27="","",IFERROR(INDEX('Aisle Loss Data'!$C$2:$C$1931,MATCH(TRIM($C27)&"|1",'Aisle Loss Data'!$E$2:$E$1931,0)),0)+IFERROR(INDEX('Aisle Loss Data'!$C$2:$C$1931,MATCH(TRIM($C27)&"|2",'Aisle Loss Data'!$E$2:$E$1931,0)),0)) -> 24298.41
A28: South1 | B28: Bengaluru | C28: BLR-Thyagaraja Nagar | D28: {=IF(C28="","",IFERROR(INDEX('CLM & IM Mapping'!$B$2:$B$270,MATCH(TRIM(C28),'CLM & IM Mapping'!$A$2:$A$270,0)),"Not Mapped"))} -> Suhas N | E28: {=IF(C28="","",IFERROR(INDEX('CLM & IM Mapping'!$C$2:$C$270,MATCH(TRIM(C28),'CLM & IM Mapping'!$A$2:$A$270,0)),"Not Mapped"))} -> Aravind S | F28: RETAIL_STORE | G28: 29203 | H28: 9567 | I28: 0 | J28: 778 | K28: 2992 | L28: 0 | M28: 0 | N28: 0 | O28: 42540 | P28: Salary Hold Request – Theft Investigation and Recovery // BLR-Thyagaraja Nagar // & Stock Adjustment Request – Theft Case // BLR-Thyagaraja Nagar / | Q28: 18000+30000=48000 | R28: Store Mass theft involvement. SLP investigation done. IR Pending | T28: =IF($C28="","",IFERROR(INDEX('Aisle Loss Data'!$B$2:$B$1931,MATCH(TRIM($C28)&"|1",'Aisle Loss Data'!$E$2:$E$1931,0)),"No Loss")&IFERROR(","&INDEX('Aisle Loss Data'!$B$2:$B$1931,MATCH(TRIM($C28)&"|2",'Aisle Loss Data'!$E$2:$E$1931,0)),"")) -> E,I | U28: =IF($C28="","",IFERROR(INDEX('Aisle Loss Data'!$C$2:$C$1931,MATCH(TRIM($C28)&"|1",'Aisle Loss Data'!$E$2:$E$1931,0)),0)+IFERROR(INDEX('Aisle Loss Data'!$C$2:$C$1931,MATCH(TRIM($C28)&"|2",'Aisle Loss Data'!$E$2:$E$1931,0)),0)) -> 20194.38
A29: South1 | B29: Bengaluru | C29: BLR-VIJAY NAGAR | D29: {=IF(C29="","",IFERROR(INDEX('CLM & IM Mapping'!$B$2:$B$270,MATCH(TRIM(C29),'CLM & IM Mapping'!$A$2:$A$270,0)),"Not Mapped"))} -> Narasimhamurthy R | E29: {=IF(C29="","",IFERROR(INDEX('CLM & IM Mapping'!$C$2:$C$270,MATCH(TRIM(C29),'CLM & IM Mapping'!$A$2:$A$270,0)),"Not Mapped"))} -> Kishor K | F29: RETAIL_STORE | G29: 16668 | H29: 23989 | I29: 0 | J29: 0 | K29: 843 | L29: 0 | M29: 0 | N29: 0 | O29: 41500 | T29: =IF($C29="","",IFERROR(INDEX('Aisle Loss Data'!$B$2:$B$1931,MATCH(TRIM($C29)&"|1",'Aisle Loss Data'!$E$2:$E$1931,0)),"No Loss")&IFERROR(","&INDEX('Aisle Loss Data'!$B$2:$B$1931,MATCH(TRIM($C29)&"|2",'Aisle Loss Data'!$E$2:$E$1931,0)),"")) -> O,D | U29: =IF($C29="","",IFERROR(INDEX('Aisle Loss Data'!$C$2:$C$1931,MATCH(TRIM($C29)&"|1",'Aisle Loss Data'!$E$2:$E$1931,0)),0)+IFERROR(INDEX('Aisle Loss Data'!$C$2:$C$1931,MATCH(TRIM($C29)&"|2",'Aisle Loss Data'!$E$2:$E$1931,0)),0)) -> 15142.83
A30: South1 | B30: Bengaluru | C30: BLR-Nikoo Home New | D30: {=IF(C30="","",IFERROR(INDEX('CLM & IM Mapping'!$B$2:$B$270,MATCH(TRIM(C30),'CLM & IM Mapping'!$A$2:$A$270,0)),"Not Mapped"))} -> Adhavan Subramani | E30: {=IF(C30="","",IFERROR(INDEX('CLM & IM Mapping'!$C$2:$C$270,MATCH(TRIM(C30),'CLM & IM Mapping'!$A$2:$A$270,0)),"Not Mapped"))} -> Mohammed Akbar | F30: RETAIL_STORE | G30: 27933 | H30: 6780 | I30: 0 | J30: 3921 | K30: 2264 | L30: 0 | M30: 180 | N30: 248 | O30: 41326 | T30: =IF($C30="","",IFERROR(INDEX('Aisle Loss Data'!$B$2:$B$1931,MATCH(TRIM($C30)&"|1",'Aisle Loss Data'!$E$2:$E$1931,0)),"No Loss")&IFERROR(","&INDEX('Aisle Loss Data'!$B$2:$B$1931,MATCH(TRIM($C30)&"|2",'Aisle Loss Data'!$E$2:$E$1931,0)),"")) -> F,H | U30: =IF($C30="","",IFERROR(INDEX('Aisle Loss Data'!$C$2:$C$1931,MATCH(TRIM($C30)&"|1",'Aisle Loss Data'!$E$2:$E$1931,0)),0)+IFERROR(INDEX('Aisle Loss Data'!$C$2:$C$1931,MATCH(TRIM($C30)&"|2",'Aisle Loss Data'!$E$2:$E$1931,0)),0)) -> 16179.07
A31: South1 | B31: Bengaluru | C31: BLR-Kogilu Road | D31: {=IF(C31="","",IFERROR(INDEX('CLM & IM Mapping'!$B$2:$B$270,MATCH(TRIM(C31),'CLM & IM Mapping'!$A$2:$A$270,0)),"Not Mapped"))} -> Adhavan Subramani | E31: {=IF(C31="","",IFERROR(INDEX('CLM & IM Mapping'!$C$2:$C$270,MATCH(TRIM(C31),'CLM & IM Mapping'!$A$2:$A$270,0)),"Not Mapped"))} -> Mohammed Akbar | F31: RETAIL_STORE | G31: 30178 | H31: 6153 | I31: 0 | J31: 3968 | K31: 810 | L31: 0 | M31: 0 | N31: 0 | O31: 41109 | T31: =IF($C31="","",IFERROR(INDEX('Aisle Loss Data'!$B$2:$B$1931,MATCH(TRIM($C31)&"|1",'Aisle Loss Data'!$E$2:$E$1931,0)),"No Loss")&IFERROR(","&INDEX('Aisle Loss Data'!$B$2:$B$1931,MATCH(TRIM($C31)&"|2",'Aisle Loss Data'!$E$2:$E$1931,0)),"")) -> K,A | U31: =IF($C31="","",IFERROR(INDEX('Aisle Loss Data'!$C$2:$C$1931,MATCH(TRIM($C31)&"|1",'Aisle Loss Data'!$E$2:$E$1931,0)),0)+IFERROR(INDEX('Aisle Loss Data'!$C$2:$C$1931,MATCH(TRIM($C31)&"|2",'Aisle Loss Data'!$E$2:$E$1931,0)),0)) -> 28949.31
A32: South1 | B32: Bengaluru | C32: BLR-INDIRANAGAR NEW | D32: {=IF(C32="","",IFERROR(INDEX('CLM & IM Mapping'!$B$2:$B$270,MATCH(TRIM(C32),'CLM & IM Mapping'!$A$2:$A$270,0)),"Not Mapped"))} -> Balaji G | E32: {=IF(C32="","",IFERROR(INDEX('CLM & IM Mapping'!$C$2:$C$270,MATCH(TRIM(C32),'CLM & IM Mapping'!$A$2:$A$270,0)),"Not Mapped"))} -> Mohammed Akbar | F32: RETAIL_STORE | G32: 29057 | H32: 9676 | I32: 340 | J32: 395 | K32: 773 | L32: 0 | M32: 0 | N32: 0 | O32: 40242 | T32: =IF($C32="","",IFERROR(INDEX('Aisle Loss Data'!$B$2:$B$1931,MATCH(TRIM($C32)&"|1",'Aisle Loss Data'!$E$2:$E$1931,0)),"No Loss")&IFERROR(","&INDEX('Aisle Loss Data'!$B$2:$B$1931,MATCH(TRIM($C32)&"|2",'Aisle Loss Data'!$E$2:$E$1931,0)),"")) -> J,M | U32: =IF($C32="","",IFERROR(INDEX('Aisle Loss Data'!$C$2:$C$1931,MATCH(TRIM($C32)&"|1",'Aisle Loss Data'!$E$2:$E$1931,0)),0)+IFERROR(INDEX('Aisle Loss Data'!$C$2:$C$1931,MATCH(TRIM($C32)&"|2",'Aisle Loss Data'!$E$2:$E$1931,0)),0)) -> 14772.64
A33: South1 | B33: Bengaluru | C33: BLR-CV RAMAN NAGAR NEW | D33: {=IF(C33="","",IFERROR(INDEX('CLM & IM Mapping'!$B$2:$B$270,MATCH(TRIM(C33),'CLM & IM Mapping'!$A$2:$A$270,0)),"Not Mapped"))} -> Silambarasan E | E33: {=IF(C33="","",IFERROR(INDEX('CLM & IM Mapping'!$C$2:$C$270,MATCH(TRIM(C33),'CLM & IM Mapping'!$A$2:$A$270,0)),"Not Mapped"))} -> Arivind S | F33: RETAIL_STORE | G33: 13995 | H33: 11558 | I33: 415 | J33: 828 | K33: 1365 | L33: 0 | M33: 2031 | N33: 9909 | O33: 40101 | T33: =IF($C33="","",IFERROR(INDEX('Aisle Loss Data'!$B$2:$B$1931,MATCH(TRIM($C33)&"|1",'Aisle Loss Data'!$E$2:$E$1931,0)),"No Loss")&IFERROR(","&INDEX('Aisle Loss Data'!$B$2:$B$1931,MATCH(TRIM($C33)&"|2",'Aisle Loss Data'!$E$2:$E$1931,0)),"")) -> G,H | U33: =IF($C33="","",IFERROR(INDEX('Aisle Loss Data'!$C$2:$C$1931,MATCH(TRIM($C33)&"|1",'Aisle Loss Data'!$E$2:$E$1931,0)),0)+IFERROR(INDEX('Aisle Loss Data'!$C$2:$C$1931,MATCH(TRIM($C33)&"|2",'Aisle Loss Data'!$E$2:$E$1931,0)),0)) -> 11355.89
A34: South1 | B34: Bengaluru | C34: BLR-Jakkur New | D34: {=IF(C34="","",IFERROR(INDEX('CLM & IM Mapping'!$B$2:$B$270,MATCH(TRIM(C34),'CLM & IM Mapping'!$A$2:$A$270,0)),"Not Mapped"))} -> Girish N | E34: {=IF(C34="","",IFERROR(INDEX('CLM & IM Mapping'!$C$2:$C$270,MATCH(TRIM(C34),'CLM & IM Mapping'!$A$2:$A$270,0)),"Not Mapped"))} -> Un Mapped | F34: RETAIL_STORE | G34: 19635 | H34: 18346 | I34: 0 | J34: 292 | K34: 1633 | L34: 0 | M34: 0 | N34: 0 | O34: 39906 | T34: =IF($C34="","",IFERROR(INDEX('Aisle Loss Data'!$B$2:$B$1931,MATCH(TRIM($C34)&"|1",'Aisle Loss Data'!$E$2:$E$1931,0)),"No Loss")&IFERROR(","&INDEX('Aisle Loss Data'!$B$2:$B$1931,MATCH(TRIM($C34)&"|2",'Aisle Loss Data'!$E$2:$E$1931,0)),"")) -> L,K | U34: =IF($C34="","",IFERROR(INDEX('Aisle Loss Data'!$C$2:$C$1931,MATCH(TRIM($C34)&"|1",'Aisle Loss Data'!$E$2:$E$1931,0)),0)+IFERROR(INDEX('Aisle Loss Data'!$C$2:$C$1931,MATCH(TRIM($C34)&"|2",'Aisle Loss Data'!$E$2:$E$1931,0)),0)) -> 16904
A35: South1 | B35: Bengaluru | C35: BLR-Kannamangala | D35: {=IF(C35="","",IFERROR(INDEX('CLM & IM Mapping'!$B$2:$B$270,MATCH(TRIM(C35),'CLM & IM Mapping'!$A$2:$A$270,0)),"Not Mapped"))} -> Ashwath S | E35: {=IF(C35="","",IFERROR(INDEX('CLM & IM Mapping'!$C$2:$C$270,MATCH(TRIM(C35),'CLM & IM Mapping'!$A$2:$A$270,0)),"Not Mapped"))} -> Kantha Kumar | F35: RETAIL_STORE | G35: 28774 | H35: 10857 | I35: 0 | J35: 0 | K35: 49 | L35: 0 | M35: 0 | N35: 0 | O35: 39679 | T35: =IF($C35="","",IFERROR(INDEX('Aisle Loss Data'!$B$2:$B$1931,MATCH(TRIM($C35)&"|1",'Aisle Loss Data'!$E$2:$E$1931,0)),"No Loss")&IFERROR(","&INDEX('Aisle Loss Data'!$B$2:$B$1931,MATCH(TRIM($C35)&"|2",'Aisle Loss Data'!$E$2:$E$1931,0)),"")) -> O,H | U35: =IF($C35="","",IFERROR(INDEX('Aisle Loss Data'!$C$2:$C$1931,MATCH(TRIM($C35)&"|1",'Aisle Loss Data'!$E$2:$E$1931,0)),0)+IFERROR(INDEX('Aisle Loss Data'!$C$2:$C$1931,MATCH(TRIM($C35)&"|2",'Aisle Loss Data'!$E$2:$E$1931,0)),0)) -> 28849.47
A36: South1 | B36: Bengaluru | C36: BLR-HSR-2 | D36: {=IF(C36="","",IFERROR(INDEX('CLM & IM Mapping'!$B$2:$B$270,MATCH(TRIM(C36),'CLM & IM Mapping'!$A$2:$A$270,0)),"Not Mapped"))} -> Saddam Hussain | E36: {=IF(C36="","",IFERROR(INDEX('CLM & IM Mapping'!$C$2:$C$270,MATCH(TRIM(C36),'CLM & IM Mapping'!$A$2:$A$270,0)),"Not Mapped"))} -> Un Mapped | F36: RETAIL_STORE | G36: 21968 | H36: 12107 | I36: 0 | J36: 5366 | K36: 0 | L36: 0 | M36: 0 | N36: 0 | O36: 39440 | T36: =IF($C36="","",IFERROR(INDEX('Aisle Loss Data'!$B$2:$B$1931,MATCH(TRIM($C36)&"|1",'Aisle Loss Data'!$E$2:$E$1931,0)),"No Loss")&IFERROR(","&INDEX('Aisle Loss Data'!$B$2:$B$1931,MATCH(TRIM($C36)&"|2",'Aisle Loss Data'!$E$2:$E$1931,0)),"")) -> L,K | U36: =IF($C36="","",IFERROR(INDEX('Aisle Loss Data'!$C$2:$C$1931,MATCH(TRIM($C36)&"|1",'Aisle Loss Data'!$E$2:$E$1931,0)),0)+IFERROR(INDEX('Aisle Loss Data'!$C$2:$C$1931,MATCH(TRIM($C36)&"|2",'Aisle Loss Data'!$E$2:$E$1931,0)),0)) -> 18504.37
A37: South1 | B37: Bengaluru | C37: BLR-Kothnur New | D37: {=IF(C37="","",IFERROR(INDEX('CLM & IM Mapping'!$B$2:$B$270,MATCH(TRIM(C37),'CLM & IM Mapping'!$A$2:$A$270,0)),"Not Mapped"))} -> Raghavendra Vernekar | E37: {=IF(C37="","",IFERROR(INDEX('CLM & IM Mapping'!$C$2:$C$270,MATCH(TRIM(C37),'CLM & IM Mapping'!$A$2:$A$270,0)),"Not Mapped"))} -> Prakash BS | F37: RETAIL_STORE | G37: 16378 | H37: 18410 | I37: 227 | J37: 2848 | K37: 751 | L37: 0 | M37: 756 | N37: 0 | O37: 39369 | T37: =IF($C37="","",IFERROR(INDEX('Aisle Loss Data'!$B$2:$B$1931,MATCH(TRIM($C37)&"|1",'Aisle Loss Data'!$E$2:$E$1931,0)),"No Loss")&IFERROR(","&INDEX('Aisle Loss Data'!$B$2:$B$1931,MATCH(TRIM($C37)&"|2",'Aisle Loss Data'!$E$2:$E$1931,0)),"")) -> A,E | U37: =IF($C37="","",IFERROR(INDEX('Aisle Loss Data'!$C$2:$C$1931,MATCH(TRIM($C37)&"|1",'Aisle Loss Data'!$E$2:$E$1931,0)),0)+IFERROR(INDEX('Aisle Loss Data'!$C$2:$C$1931,MATCH(TRIM($C37)&"|2",'Aisle Loss Data'!$E$2:$E$1931,0)),0)) -> 17205.59
A38: South1 | B38: Bengaluru | C38: BLR-Marathalli SS | D38: {=IF(C38="","",IFERROR(INDEX('CLM & IM Mapping'!$B$2:$B$270,MATCH(TRIM(C38),'CLM & IM Mapping'!$A$2:$A$270,0)),"Not Mapped"))} -> Arun Raj | E38: {=IF(C38="","",IFERROR(INDEX('CLM & IM Mapping'!$C$2:$C$270,MATCH(TRIM(C38),'CLM & IM Mapping'!$A$2:$A$270,0)),"Not Mapped"))} -> Simon Manoharan | F38: SUPERSTORE | G38: 23481 | H38: 11376 | I38: 0 | J38: 0 | K38: 3479 | L38: 0 | M38: 0 | N38: 0 | O38: 38336 | T38: =IF($C38="","",IFERROR(INDEX('Aisle Loss Data'!$B$2:$B$1931,MATCH(TRIM($C38)&"|1",'Aisle Loss Data'!$E$2:$E$1931,0)),"No Loss")&IFERROR(","&INDEX('Aisle Loss Data'!$B$2:$B$1931,MATCH(TRIM($C38)&"|2",'Aisle Loss Data'!$E$2:$E$1931,0)),"")) -> I,M | U38: =IF($C38="","",IFERROR(INDEX('Aisle Loss Data'!$C$2:$C$1931,MATCH(TRIM($C38)&"|1",'Aisle Loss Data'!$E$2:$E$1931,0)),0)+IFERROR(INDEX('Aisle Loss Data'!$C$2:$C$1931,MATCH(TRIM($C38)&"|2",'Aisle Loss Data'!$E$2:$E$1931,0)),0)) -> 14286.65
A39: South1 | B39: Bengaluru | C39: BLR-Dasarahalli | D39: {=IF(C39="","",IFERROR(INDEX('CLM & IM Mapping'!$B$2:$B$270,MATCH(TRIM(C39),'CLM & IM Mapping'!$A$2:$A$270,0)),"Not Mapped"))} -> Mohaideen DH | E39: {=IF(C39="","",IFERROR(INDEX('CLM & IM Mapping'!$C$2:$C$270,MATCH(TRIM(C39),'CLM & IM Mapping'!$A$2:$A$270,0)),"Not Mapped"))} -> Mohammed Akbar | F39: RETAIL_STORE | G39: 7420 | H39: 28642 | I39: 116 | J39: 710 | K39: 298 | L39: 0 | M39: 0 | N39: 0 | O39: 37186 | T39: =IF($C39="","",IFERROR(INDEX('Aisle Loss Data'!$B$2:$B$1931,MATCH(TRIM($C39)&"|1",'Aisle Loss Data'!$E$2:$E$1931,0)),"No Loss")&IFERROR(","&INDEX('Aisle Loss Data'!$B$2:$B$1931,MATCH(TRIM($C39)&"|2",'Aisle Loss Data'!$E$2:$E$1931,0)),"")) -> A,C | U39: =IF($C39="","",IFERROR(INDEX('Aisle Loss Data'!$C$2:$C$1931,MATCH(TRIM($C39)&"|1",'Aisle Loss Data'!$E$2:$E$1931,0)),0)+IFERROR(INDEX('Aisle Loss Data'!$C$2:$C$1931,MATCH(TRIM($C39)&"|2",'Aisle Loss Data'!$E$2:$E$1931,0)),0)) -> 30449.02
A40: South1 | B40: Bengaluru | C40: BLR-Manjunatha layout | D40: {=IF(C40="","",IFERROR(INDEX('CLM & IM Mapping'!$B$2:$B$270,MATCH(TRIM(C40),'CLM & IM Mapping'!$A$2:$A$270,0)),"Not Mapped"))} -> Sundaresh S | E40: {=IF(C40="","",IFERROR(INDEX('CLM & IM Mapping'!$C$2:$C$270,MATCH(TRIM(C40),'CLM & IM Mapping'!$A$2:$A$270,0)),"Not Mapped"))} -> Un Mapped | F40: RETAIL_STORE | G40: 15298 | H40: 12439 | I40: 0 | J40: 1021 | K40: 1315 | L40: 0 | M40: 7022 | N40: 0 | O40: 37095 | T40: =IF($C40="","",IFERROR(INDEX('Aisle Loss Data'!$B$2:$B$1931,MATCH(TRIM($C40)&"|1",'Aisle Loss Data'!$E$2:$E$1931,0)),"No Loss")&IFERROR(","&INDEX('Aisle Loss Data'!$B$2:$B$1931,MATCH(TRIM($C40)&"|2",'Aisle Loss Data'!$E$2:$E$1931,0)),"")) -> H,C | U40: =IF($C40="","",IFERROR(INDEX('Aisle Loss Data'!$C$2:$C$1931,MATCH(TRIM($C40)&"|1",'Aisle Loss Data'!$E$2:$E$1931,0)),0)+IFERROR(INDEX('Aisle Loss Data'!$C$2:$C$1931,MATCH(TRIM($C40)&"|2",'Aisle Loss Data'!$E$2:$E$1931,0)),0)) -> 16593.83
...

Sheet Inventory Hygiene
A1: store_name | B1: CLM | C1: IM | D1: sub_store_type | E1: planogram_enabled_flag | F1: city_name | G1: Total Bins | H1: Target CC MTD | I1: CC MTD % | J1: BA MTD % | K1: IA MTD % | L1: CC ACC % | M1: CCA | N1: RCA & POA | O1: ETA
A2: BLR-Vidyaranyapura | B2: {=IF(A2="","",IFERROR(INDEX('CLM & IM Mapping'!$B$2:$B$270,MATCH(TRIM(A2),'CLM & IM Mapping'!$A$2:$A$270,0)),"Not Mapped"))} -> Akshay P | C2: {=IF(A2="","",IFERROR(INDEX('CLM & IM Mapping'!$C$2:$C$270,MATCH(TRIM(A2),'CLM & IM Mapping'!$A$2:$A$270,0)),"Not Mapped"))} -> Srittam Dhal | D2: RETAIL_STORE | E2: Yes | F2: Bengaluru | G2: 5212 | H2: 0.7 | I2: 0 | M2: 1
A3: BLR-BROOKEFIELD | B3: {=IF(A3="","",IFERROR(INDEX('CLM & IM Mapping'!$B$2:$B$270,MATCH(TRIM(A3),'CLM & IM Mapping'!$A$2:$A$270,0)),"Not Mapped"))} -> Basil Scariya | C3: {=IF(A3="","",IFERROR(INDEX('CLM & IM Mapping'!$C$2:$C$270,MATCH(TRIM(A3),'CLM & IM Mapping'!$A$2:$A$270,0)),"Not Mapped"))} -> Prakash BS | D3: RETAIL_STORE | E3: Yes | F3: Bengaluru | G3: 7849 | H3: 0.7 | I3: 0
A4: BLR-Vidyaranyapura SS | B4: {=IF(A4="","",IFERROR(INDEX('CLM & IM Mapping'!$B$2:$B$270,MATCH(TRIM(A4),'CLM & IM Mapping'!$A$2:$A$270,0)),"Not Mapped"))} -> Arun Raj | C4: {=IF(A4="","",IFERROR(INDEX('CLM & IM Mapping'!$C$2:$C$270,MATCH(TRIM(A4),'CLM & IM Mapping'!$A$2:$A$270,0)),"Not Mapped"))} -> Simon Manoharan | D4: SUPERSTORE | E4: No | F4: Bengaluru | G4: 12051 | H4: 0.7 | I4: 0
A5: BLR-JC Nagar | B5: {=IF(A5="","",IFERROR(INDEX('CLM & IM Mapping'!$B$2:$B$270,MATCH(TRIM(A5),'CLM & IM Mapping'!$A$2:$A$270,0)),"Not Mapped"))} -> Manoj Kj | C5: {=IF(A5="","",IFERROR(INDEX('CLM & IM Mapping'!$C$2:$C$270,MATCH(TRIM(A5),'CLM & IM Mapping'!$A$2:$A$270,0)),"Not Mapped"))} -> Srittam Dhal | D5: RETAIL_STORE | E5: Yes | F5: Bengaluru | G5: 5421 | H5: 0.7 | I5: 0.01 | J5: 0.97 | K5: 0.99 | L5: 0.06 | M5: 5
A6: BLR-Balagere SS | B6: {=IF(A6="","",IFERROR(INDEX('CLM & IM Mapping'!$B$2:$B$270,MATCH(TRIM(A6),'CLM & IM Mapping'!$A$2:$A$270,0)),"Not Mapped"))} -> Arun Raj | C6: {=IF(A6="","",IFERROR(INDEX('CLM & IM Mapping'!$C$2:$C$270,MATCH(TRIM(A6),'CLM & IM Mapping'!$A$2:$A$270,0)),"Not Mapped"))} -> Simon Manoharan | D6: SUPERSTORE | E6: No | F6: Bengaluru | G6: 10619 | H6: 0.7 | I6: 0.02 | J6: 0 | K6: -22.56 | L6: 0
A7: BLR-JP Nagar SS | B7: {=IF(A7="","",IFERROR(INDEX('CLM & IM Mapping'!$B$2:$B$270,MATCH(TRIM(A7),'CLM & IM Mapping'!$A$2:$A$270,0)),"Not Mapped"))} -> Arun Raj | C7: {=IF(A7="","",IFERROR(INDEX('CLM & IM Mapping'!$C$2:$C$270,MATCH(TRIM(A7),'CLM & IM Mapping'!$A$2:$A$270,0)),"Not Mapped"))} -> Simon Manoharan | D7: SUPERSTORE | E7: No | F7: Bengaluru | G7: 13730 | H7: 0.7 | I7: 0.06 | J7: 0.96 | K7: 0.98 | L7: 0.26 | M7: 1
A8: BLR-Eldorado | B8: {=IF(A8="","",IFERROR(INDEX('CLM & IM Mapping'!$B$2:$B$270,MATCH(TRIM(A8),'CLM & IM Mapping'!$A$2:$A$270,0)),"Not Mapped"))} -> Adhavan Subramani | C8: {=IF(A8="","",IFERROR(INDEX('CLM & IM Mapping'!$C$2:$C$270,MATCH(TRIM(A8),'CLM & IM Mapping'!$A$2:$A$270,0)),"Not Mapped"))} -> Mohammed Akbar | D8: RETAIL_STORE | E8: Yes | F8: Bengaluru | G8: 5759 | H8: 0.7 | I8: 0.07 | J8: 0.92 | K8: 0.92
A9: COI-R S Puram | B9: {=IF(A9="","",IFERROR(INDEX('CLM & IM Mapping'!$B$2:$B$270,MATCH(TRIM(A9),'CLM & IM Mapping'!$A$2:$A$270,0)),"Not Mapped"))} -> John Britto | C9: {=IF(A9="","",IFERROR(INDEX('CLM & IM Mapping'!$C$2:$C$270,MATCH(TRIM(A9),'CLM & IM Mapping'!$A$2:$A$270,0)),"Not Mapped"))} -> Aravind S | D9: RETAIL_STORE | E9: Yes | F9: Coimbatore | G9: 5114 | H9: 0.7 | I9: 0.07 | J9: 0.94 | K9: 0.96 | L9: 0.31 | M9: 1
A10: COI-Parashakti nagar | B10: {=IF(A10="","",IFERROR(INDEX('CLM & IM Mapping'!$B$2:$B$270,MATCH(TRIM(A10),'CLM & IM Mapping'!$A$2:$A$270,0)),"Not Mapped"))} -> John Britto | C10: {=IF(A10="","",IFERROR(INDEX('CLM & IM Mapping'!$C$2:$C$270,MATCH(TRIM(A10),'CLM & IM Mapping'!$A$2:$A$270,0)),"Not Mapped"))} -> Aravind S | D10: RETAIL_STORE | E10: Yes | F10: Coimbatore | G10: 6188 | H10: 0.7 | I10: 0.1 | J10: 0.81 | K10: 0.98 | L10: 0.35 | M10: 3
A11: COI-Sundarapuram | B11: {=IF(A11="","",IFERROR(INDEX('CLM & IM Mapping'!$B$2:$B$270,MATCH(TRIM(A11),'CLM & IM Mapping'!$A$2:$A$270,0)),"Not Mapped"))} -> John Britto | C11: {=IF(A11="","",IFERROR(INDEX('CLM & IM Mapping'!$C$2:$C$270,MATCH(TRIM(A11),'CLM & IM Mapping'!$A$2:$A$270,0)),"Not Mapped"))} -> Aravind S | D11: RETAIL_STORE | E11: Yes | F11: Coimbatore | G11: 6277 | H11: 0.7 | I11: 0.1 | J11: 0.81 | K11: 0.97 | L11: 0.37 | M11: 2
A12: KOC-Kalamassery SS | B12: {=IF(A12="","",IFERROR(INDEX('CLM & IM Mapping'!$B$2:$B$270,MATCH(TRIM(A12),'CLM & IM Mapping'!$A$2:$A$270,0)),"Not Mapped"))} -> Vishnu V | C12: {=IF(A12="","",IFERROR(INDEX('CLM & IM Mapping'!$C$2:$C$270,MATCH(TRIM(A12),'CLM & IM Mapping'!$A$2:$A$270,0)),"Not Mapped"))} -> Arivind S | D12: SUPERSTORE | E12: No | F12: Kochi | G12: 6058 | H12: 0.7 | I12: 0.12 | J12: 0.99 | K12: 1 | L12: 0.52 | M12: 1
A13: BLR-RICHMOND TOWN SS | B13: {=IF(A13="","",IFERROR(INDEX('CLM & IM Mapping'!$B$2:$B$270,MATCH(TRIM(A13),'CLM & IM Mapping'!$A$2:$A$270,0)),"Not Mapped"))} -> Arun Raj | C13: {=IF(A13="","",IFERROR(INDEX('CLM & IM Mapping'!$C$2:$C$270,MATCH(TRIM(A13),'CLM & IM Mapping'!$A$2:$A$270,0)),"Not Mapped"))} -> Simon Manoharan | D13: SUPERSTORE | E13: No | F13: Bengaluru | G13: 12938 | H13: 0.7 | I13: 0.13 | J13: 0.77 | K13: 0.92 | L13: 0.46 | M13: 4
A14: BLR-Malleshwaram SS | B14: {=IF(A14="","",IFERROR(INDEX('CLM & IM Mapping'!$B$2:$B$270,MATCH(TRIM(A14),'CLM & IM Mapping'!$A$2:$A$270,0)),"Not Mapped"))} -> Arun Raj | C14: {=IF(A14="","",IFERROR(INDEX('CLM & IM Mapping'!$C$2:$C$270,MATCH(TRIM(A14),'CLM & IM Mapping'!$A$2:$A$270,0)),"Not Mapped"))} -> Simon Manoharan | D14: SUPERSTORE | E14: No | F14: Bengaluru | G14: 7680 | H14: 0.7 | I14: 0.14 | J14: 0.76 | K14: 0.96 | L14: 0.46 | M14: 1
A15: BLR-RR Nagar SS | B15: {=IF(A15="","",IFERROR(INDEX('CLM & IM Mapping'!$B$2:$B$270,MATCH(TRIM(A15),'CLM & IM Mapping'!$A$2:$A$270,0)),"Not Mapped"))} -> Arun Raj | C15: {=IF(A15="","",IFERROR(INDEX('CLM & IM Mapping'!$C$2:$C$270,MATCH(TRIM(A15),'CLM & IM Mapping'!$A$2:$A$270,0)),"Not Mapped"))} -> Simon Manoharan | D15: SUPERSTORE | E15: No | F15: Bengaluru | G15: 11984 | H15: 0.7 | I15: 0.14 | J15: 0.94 | K15: 0.99 | L15: 0.6
A16: COI-Nehru Nagar | B16: {=IF(A16="","",IFERROR(INDEX('CLM & IM Mapping'!$B$2:$B$270,MATCH(TRIM(A16),'CLM & IM Mapping'!$A$2:$A$270,0)),"Not Mapped"))} -> John Britto | C16: {=IF(A16="","",IFERROR(INDEX('CLM & IM Mapping'!$C$2:$C$270,MATCH(TRIM(A16),'CLM & IM Mapping'!$A$2:$A$270,0)),"Not Mapped"))} -> Aravind S | D16: RETAIL_STORE | E16: Yes | F16: Coimbatore | G16: 6791 | H16: 0.7 | I16: 0.14 | J16: 0.98 | K16: 1
A17: BLR-Jakkur Network | B17: {=IF(A17="","",IFERROR(INDEX('CLM & IM Mapping'!$B$2:$B$270,MATCH(TRIM(A17),'CLM & IM Mapping'!$A$2:$A$270,0)),"Not Mapped"))} -> Girish N | C17: {=IF(A17="","",IFERROR(INDEX('CLM & IM Mapping'!$C$2:$C$270,MATCH(TRIM(A17),'CLM & IM Mapping'!$A$2:$A$270,0)),"Not Mapped"))} -> Un Mapped | D17: RETAIL_STORE | E17: Yes | F17: Bengaluru | G17: 5106 | H17: 0.7 | I17: 0.16 | J17: 0.69 | K17: 0.98 | L17: 0.49 | M17: 11
A18: COI-Race Course | B18: {=IF(A18="","",IFERROR(INDEX('CLM & IM Mapping'!$B$2:$B$270,MATCH(TRIM(A18),'CLM & IM Mapping'!$A$2:$A$270,0)),"Not Mapped"))} -> John Britto | C18: {=IF(A18="","",IFERROR(INDEX('CLM & IM Mapping'!$C$2:$C$270,MATCH(TRIM(A18),'CLM & IM Mapping'!$A$2:$A$270,0)),"Not Mapped"))} -> Aravind S | D18: RETAIL_STORE | E18: Yes | F18: Coimbatore | G18: 7163 | H18: 0.7 | I18: 0.18 | J18: 0.91 | K18: 0.97 | L18: 0.72 | M18: 1
A19: KOC-PALLURTHY | B19: {=IF(A19="","",IFERROR(INDEX('CLM & IM Mapping'!$B$2:$B$270,MATCH(TRIM(A19),'CLM & IM Mapping'!$A$2:$A$270,0)),"Not Mapped"))} -> Vishnu V | C19: {=IF(A19="","",IFERROR(INDEX('CLM & IM Mapping'!$C$2:$C$270,MATCH(TRIM(A19),'CLM & IM Mapping'!$A$2:$A$270,0)),"Not Mapped"))} -> Arivind S | D19: RETAIL_STORE | E19: Yes | F19: Kochi | G19: 5139 | H19: 0.7 | I19: 0.18 | J19: 0.7 | K19: 0.92 | L19: 0.55 | M19: 1
A20: BLR-VIJAY NAGAR | B20: {=IF(A20="","",IFERROR(INDEX('CLM & IM Mapping'!$B$2:$B$270,MATCH(TRIM(A20),'CLM & IM Mapping'!$A$2:$A$270,0)),"Not Mapped"))} -> Narasimhamurthy R | C20: {=IF(A20="","",IFERROR(INDEX('CLM & IM Mapping'!$C$2:$C$270,MATCH(TRIM(A20),'CLM & IM Mapping'!$A$2:$A$270,0)),"Not Mapped"))} -> Kishor K | D20: RETAIL_STORE | E20: No | F20: Bengaluru | G20: 5482 | H20: 0.7 | I20: 0.19 | J20: 0.6 | K20: 0.88 | L20: 0.5 | M20: 3
A21: BLR-Dooravani Nagar SS | B21: {=IF(A21="","",IFERROR(INDEX('CLM & IM Mapping'!$B$2:$B$270,MATCH(TRIM(A21),'CLM & IM Mapping'!$A$2:$A$270,0)),"Not Mapped"))} -> Arun Raj | C21: {=IF(A21="","",IFERROR(INDEX('CLM & IM Mapping'!$C$2:$C$270,MATCH(TRIM(A21),'CLM & IM Mapping'!$A$2:$A$270,0)),"Not Mapped"))} -> Simon Manoharan | D21: SUPERSTORE | E21: No | F21: Bengaluru | G21: 12201 | H21: 0.7 | I21: 0.21 | J21: 0.92 | K21: 0.96 | L21: 0.86 | M21: 3
A22: COI-Vadavalli 1 | B22: {=IF(A22="","",IFERROR(INDEX('CLM & IM Mapping'!$B$2:$B$270,MATCH(TRIM(A22),'CLM & IM Mapping'!$A$2:$A$270,0)),"Not Mapped"))} -> John Britto | C22: {=IF(A22="","",IFERROR(INDEX('CLM & IM Mapping'!$C$2:$C$270,MATCH(TRIM(A22),'CLM & IM Mapping'!$A$2:$A$270,0)),"Not Mapped"))} -> Aravind S | D22: RETAIL_STORE | E22: Yes | F22: Coimbatore | G22: 7099 | H22: 0.7 | I22: 0.21 | J22: 0.96 | K22: 0.97 | L22: 0.9 | M22: 1
A23: BLR-BASAVANAPURA | B23: {=IF(A23="","",IFERROR(INDEX('CLM & IM Mapping'!$B$2:$B$270,MATCH(TRIM(A23),'CLM & IM Mapping'!$A$2:$A$270,0)),"Not Mapped"))} -> Richard Harris | C23: {=IF(A23="","",IFERROR(INDEX('CLM & IM Mapping'!$C$2:$C$270,MATCH(TRIM(A23),'CLM & IM Mapping'!$A$2:$A$270,0)),"Not Mapped"))} -> Kantha Kumar | D23: RETAIL_STORE | E23: Yes | F23: Bengaluru | G23: 4538 | H23: 0.7 | I23: 0.22 | J23: 0.41 | K23: 0.83 | L23: 0.39 | M23: 3
A24: BLR-HSR Layout New | B24: {=IF(A24="","",IFERROR(INDEX('CLM & IM Mapping'!$B$2:$B$270,MATCH(TRIM(A24),'CLM & IM Mapping'!$A$2:$A$270,0)),"Not Mapped"))} -> Saddam Hussain | C24: {=IF(A24="","",IFERROR(INDEX('CLM & IM Mapping'!$C$2:$C$270,MATCH(TRIM(A24),'CLM & IM Mapping'!$A$2:$A$270,0)),"Not Mapped"))} -> Un Mapped | D24: RETAIL_STORE | E24: Yes | F24: Bengaluru | G24: 6691 | H24: 0.7 | I24: 0.23 | J24: 0.73 | K24: 0.86 | L24: 0.73 | M24: 3
A25: BLR-Electronic City SS | B25: {=IF(A25="","",IFERROR(INDEX('CLM & IM Mapping'!$B$2:$B$270,MATCH(TRIM(A25),'CLM & IM Mapping'!$A$2:$A$270,0)),"Not Mapped"))} -> Arun Raj | C25: {=IF(A25="","",IFERROR(INDEX('CLM & IM Mapping'!$C$2:$C$270,MATCH(TRIM(A25),'CLM & IM Mapping'!$A$2:$A$270,0)),"Not Mapped"))} -> Simon Manoharan | D25: SUPERSTORE | E25: No | F25: Bengaluru | G25: 11048 | H25: 0.7 | I25: 0.23 | J25: 0.97 | K25: 0.99 | L25: 0.97 | M25: 1
A26: BLR-Bellandur SS | B26: {=IF(A26="","",IFERROR(INDEX('CLM & IM Mapping'!$B$2:$B$270,MATCH(TRIM(A26),'CLM & IM Mapping'!$A$2:$A$270,0)),"Not Mapped"))} -> Arun Raj | C26: {=IF(A26="","",IFERROR(INDEX('CLM & IM Mapping'!$C$2:$C$270,MATCH(TRIM(A26),'CLM & IM Mapping'!$A$2:$A$270,0)),"Not Mapped"))} -> Simon Manoharan | D26: SUPERSTORE | E26: No | F26: Bengaluru | G26: 10796 | H26: 0.7 | I26: 0.23 | J26: 0.97 | K26: 0.99 | L26: 0.97 | M26: 1
A27: BLR-Mico layout New | B27: {=IF(A27="","",IFERROR(INDEX('CLM & IM Mapping'!$B$2:$B$270,MATCH(TRIM(A27),'CLM & IM Mapping'!$A$2:$A$270,0)),"Not Mapped"))} -> Keshav G | C27: {=IF(A27="","",IFERROR(INDEX('CLM & IM Mapping'!$C$2:$C$270,MATCH(TRIM(A27),'CLM & IM Mapping'!$A$2:$A$270,0)),"Not Mapped"))} -> Un Mapped | D27: RETAIL_STORE | E27: Yes | F27: Bengaluru | G27: 5873 | H27: 0.7 | I27: 0.25 | J27: 0.73 | K27: 0.95 | L27: 0.73 | M27: 6
A28: BLR-Kothnur New | B28: {=IF(A28="","",IFERROR(INDEX('CLM & IM Mapping'!$B$2:$B$270,MATCH(TRIM(A28),'CLM & IM Mapping'!$A$2:$A$270,0)),"Not Mapped"))} -> Raghavendra Vernekar | C28: {=IF(A28="","",IFERROR(INDEX('CLM & IM Mapping'!$C$2:$C$270,MATCH(TRIM(A28),'CLM & IM Mapping'!$A$2:$A$270,0)),"Not Mapped"))} -> Prakash BS | D28: RETAIL_STORE | E28: Yes | F28: Bengaluru | G28: 5574 | H28: 0.7 | I28: 0.25 | J28: 0.78 | K28: 0.94 | L28: 0.78 | M28: 3
... A31: KOC-Edappally | B31: {=IF(A31="","",IFERROR(INDEX('CLM & IM Mapping'!$B$2:$B$270,MATCH(TRIM(A31),'CLM & IM Mapping'!$A$2:$A$270,0)),"Not Mapped"))} -> Vishnu V | C31: {=IF(A31="","",IFERROR(INDEX('CLM & IM Mapping'!$C$2:$C$270,MATCH(TRIM(A31),'CLM & IM Mapping'!$A$2:$A$270,0)),"Not Mapped"))} -> Arivind S | D31: RETAIL_STORE | E31: Yes | F31: Kochi | G31: 6097 | H31: 0.7 | I31: 0.26 | J31: 0.91 | K31: 0.92 | L31: 0.91 | M31: 1
A32: PAL-Kalpathy | B32: {=IF(A32="","",IFERROR(INDEX('CLM & IM Mapping'!$B$2:$B$270,MATCH(TRIM(A32),'CLM & IM Mapping'!$A$2:$A$270,0)),"Not Mapped"))} -> Vishnu V | C32: {=IF(A32="","",IFERROR(INDEX('CLM & IM Mapping'!$C$2:$C$270,MATCH(TRIM(A32),'CLM & IM Mapping'!$A$2:$A$270,0)),"Not Mapped"))} -> Arivind S | D32: RETAIL_STORE | E32: Yes | F32: Palakkad | G32: 5121 | H32: 0.7 | I32: 0.26 | J32: 0.94 | K32: 0.99 | L32: 0.94
A33: BLR-Nehru Nagar SS | B33: {=IF(A33="","",IFERROR(INDEX('CLM & IM Mapping'!$B$2:$B$270,MATCH(TRIM(A33),'CLM & IM Mapping'!$A$2:$A$270,0)),"Not Mapped"))} -> Arun Raj | C33: {=IF(A33="","",IFERROR(INDEX('CLM & IM Mapping'!$C$2:$C$270,MATCH(TRIM(A33),'CLM & IM Mapping'!$A$2:$A$270,0)),"Not Mapped"))} -> Simon Manoharan | D33: SUPERSTORE | E33: No | F33: Bengaluru | G33: 13736 | H33: 0.7 | I33: 0.27 | J33: 0.97 | K33: 0.99 | L33: 0.97 | M33: 1
A34: COI-Peelamedu | B34: {=IF(A34="","",IFERROR(INDEX('CLM & IM Mapping'!$B$2:$B$270,MATCH(TRIM(A34),'CLM & IM Mapping'!$A$2:$A$270,0)),"Not Mapped"))} -> John Britto | C34: {=IF(A34="","",IFERROR(INDEX('CLM & IM Mapping'!$C$2:$C$270,MATCH(TRIM(A34),'CLM & IM Mapping'!$A$2:$A$270,0)),"Not Mapped"))} -> Aravind S | D34: RETAIL_STORE | E34: Yes | F34: Coimbatore | G34: 6707 | H34: 0.7 | I34: 0.27 | J34: 0.82 | K34: 0.95 | L34: 0.82 | M34: 3
A35: BLR-Marathahalli-3 | B35: {=IF(A35="","",IFERROR(INDEX('CLM & IM Mapping'!$B$2:$B$270,MATCH(TRIM(A35),'CLM & IM Mapping'!$A$2:$A$270,0)),"Not Mapped"))} -> Sundaresh S | C35: {=IF(A35="","",IFERROR(INDEX('CLM & IM Mapping'!$C$2:$C$270,MATCH(TRIM(A35),'CLM & IM Mapping'!$A$2:$A$270,0)),"Not Mapped"))} -> Un Mapped | D35: RETAIL_STORE | E35: Yes | F35: Bengaluru | G35: 6352 | H35: 0.7 | I35: 0.29 | J35: 0.69 | K35: 0.93 | L35: 0.69 | M35: 2
A36: BLR-Nikoo home SS | B36: {=IF(A36="","",IFERROR(INDEX('CLM & IM Mapping'!$B$2:$B$270,MATCH(TRIM(A36),'CLM & IM Mapping'!$A$2:$A$270,0)),"Not Mapped"))} -> Arun Raj | C36: {=IF(A36="","",IFERROR(INDEX('CLM & IM Mapping'!$C$2:$C$270,MATCH(TRIM(A36),'CLM & IM Mapping'!$A$2:$A$270,0)),"Not Mapped"))} -> Simon Manoharan | D36: SUPERSTORE | E36: No | F36: Bengaluru | G36: 13152 | H36: 0.7 | I36: 0.3 | J36: 0.97 | K36: 0.98 | L36: 0.97 | M36: 2
A37: BLR-Silver County SS | B37: {=IF(A37="","",IFERROR(INDEX('CLM & IM Mapping'!$B$2:$B$270,MATCH(TRIM(A37),'CLM & IM Mapping'!$A$2:$A$270,0)),"Not Mapped"))} -> Arun Raj | C37: {=IF(A37="","",IFERROR(INDEX('CLM & IM Mapping'!$C$2:$C$270,MATCH(TRIM(A37),'CLM & IM Mapping'!$A$2:$A$270,0)),"Not Mapped"))} -> Simon Manoharan | D37: SUPERSTORE | E37: Yes | F37: Bengaluru | G37: 10893 | H37: 0.7 | I37: 0.3 | J37: 0.97 | K37: 0.99 | L37: 0.97 | M37: =#N/A -> #N/A
A38: BLR-Sattava East SS | B38: {=IF(A38="","",IFERROR(INDEX('CLM & IM Mapping'!$B$2:$B$270,MATCH(TRIM(A38),'CLM & IM Mapping'!$A$2:$A$270,0)),"Not Mapped"))} -> Arun Raj | C38: {=IF(A38="","",IFERROR(INDEX('CLM & IM Mapping'!$C$2:$C$270,MATCH(TRIM(A38),'CLM & IM Mapping'!$A$2:$A$270,0)),"Not Mapped"))} -> Simon Manoharan | D38: SUPERSTORE | E38: No | F38: Bengaluru | G38: 12271 | H38: 0.7 | I38: 0.3 | J38: 0.99 | K38: 1 | L38: 0.99 | M38: 2
A39: BLR-Bagalakunte | B39: {=IF(A39="","",IFERROR(INDEX('CLM & IM Mapping'!$B$2:$B$270,MATCH(TRIM(A39),'CLM & IM Mapping'!$A$2:$A$270,0)),"Not Mapped"))} -> Akshay P | C39: {=IF(A39="","",IFERROR(INDEX('CLM & IM Mapping'!$C$2:$C$270,MATCH(TRIM(A39),'CLM & IM Mapping'!$A$2:$A$270,0)),"Not Mapped"))} -> Srittam Dhal | D39: RETAIL_STORE | E39: Yes | F39: Bengaluru | G39: 7531 | H39: 0.7 | I39: 0.31 | J39: 0.82 | K39: 0.89 | L39: 0.82 | M39: 2
A40: BLR-HSR-2 | B40: {=IF(A40="","",IFERROR(INDEX('CLM & IM Mapping'!$B$2:$B$270,MATCH(TRIM(A40),'CLM & IM Mapping'!$A$2:$A$270,0)),"Not Mapped"))} -> Saddam Hussain | C40: {=IF(A40="","",IFERROR(INDEX('CLM & IM Mapping'!$C$2:$C$270,MATCH(TRIM(A40),'CLM & IM Mapping'!$A$2:$A$270,0)),"Not Mapped"))} -> Un Mapped | D40: RETAIL_STORE | E40: No | F40: Bengaluru | G40: 5314 | H40: 0.7 | I40: 0.32 | J40: 0.78 | K40: 0.97 | L40: 0.78 | M40: 4
A41: BLR-Doddakannelli SS | B41: {=IF(A41="","",IFERROR(INDEX('CLM & IM Mapping'!$B$2:$B$270,MATCH(TRIM(A41),'CLM & IM Mapping'!$A$2:$A$270,0)),"Not Mapped"))} -> Arun Raj | C41: {=IF(A41="","",IFERROR(INDEX('CLM & IM Mapping'!$C$2:$C$270,MATCH(TRIM(A41),'CLM & IM Mapping'!$A$2:$A$270,0)),"Not Mapped"))} -> Simon Manoharan | D41: SUPERSTORE | E41: No | F41: Bengaluru | G41: 13860 | H41: 0.7 | I41: 0.32 | J41: 0.97 | K41: 0.99 | L41: 0.97 | M41: 2
A42: BLR-Seegehalli | B42: {=IF(A42="","",IFERROR(INDEX('CLM & IM Mapping'!$B$2:$B$270,MATCH(TRIM(A42),'CLM & IM Mapping'!$A$2:$A$270,0)),"Not Mapped"))} -> Richard Harris | C42: {=IF(A42="","",IFERROR(INDEX('CLM & IM Mapping'!$C$2:$C$270,MATCH(TRIM(A42),'CLM & IM Mapping'!$A$2:$A$270,0)),"Not Mapped"))} -> Kantha Kumar | D42: RETAIL_STORE | E42: Yes | F42: Bengaluru | G42: 6404 | H42: 0.7 | I42: 0.32 | J42: 0.81 | K42: 0.93 | L42: 0.81 | M42: 4
...

Sheet CLM & IM Mapping
A1: Store Names | B1: CLM Updated | C1: New IM Mapping
A2: BLR-Sarjapur New | B2: Saddam Hussain | C2: Un Mapped
A3: BLR-Agrahara Road | B3: Saddam Hussain | C3: Un Mapped
A4: BLR-Sarjapur-2 | B4: Saddam Hussain | C4: Un Mapped
A5: BLR-Doddakannelli | B5: Sundaresh S | C5: Un Mapped
A6: BLR-Carmelaram | B6: Sundaresh S | C6: Un Mapped
A7: BLR-Kasavanahalli | B7: Saddam Hussain | C7: Un Mapped
A8: BLR-Kasturinagar New | B8: Rizwan Ahmed | C8: Un Mapped
A9: BLR-Dooravani Nagar | B9: Rizwan Ahmed | C9: Un Mapped
A10: BLR-TC Palaya | B10: Rizwan Ahmed | C10: Un Mapped
A11: BLR-Banjara Layout | B11: Rizwan Ahmed | C11: Un Mapped
A12: BLR-Ramamurthy Nagar Network | B12: Rizwan Ahmed | C12: Un Mapped
... A270: TIR-Thiru VK Nagar Road | B270: John Britto | C270: Aravind S

Sheet Bad Bins
A1: Row Labels | B1: CLM | C1: IM | D1: DAMAGEBIN | E1: EXPIRYBIN | F1: QUALITYBIN | G1: REINVENTORY-DAMAGEBIN | H1: REINVENTORY-QUALITYBIN | I1: SCRAPBIN | J1: Grand Total | K1: Created_last_24_hours | L1: RCA & POA | M1: ETA
A2: KOC-Infopark | B2: {=IF(A2="","",IFERROR(INDEX('CLM & IM Mapping'!$B$2:$B$270,MATCH(TRIM(A2),'CLM & IM Mapping'!$A$2:$A$270,0)),"Not Mapped"))} -> Vishnu V | C2: {=IF(A2="","",IFERROR(INDEX('CLM & IM Mapping'!$C$2:$C$270,MATCH(TRIM(A2),'CLM & IM Mapping'!$A$2:$A$270,0)),"Not Mapped"))} -> Arivind S | D2: 100 | E2: 1694 | F2: 31 | G2: 8 | H2: 0 | I2: 24 | J2: 1857 | K2: 69
A3: BLR-SHIVAJI NAGAR Network | B3: {=IF(A3="","",IFERROR(INDEX('CLM & IM Mapping'!$B$2:$B$270,MATCH(TRIM(A3),'CLM & IM Mapping'!$A$2:$A$270,0)),"Not Mapped"))} -> Vijay M | C3: {=IF(A3="","",IFERROR(INDEX('CLM & IM Mapping'!$C$2:$C$270,MATCH(TRIM(A3),'CLM & IM Mapping'!$A$2:$A$270,0)),"Not Mapped"))} -> Kantha Kumar | D3: 0 | E3: 11 | F3: 0 | G3: 167 | H3: 830 | I3: 44 | J3: 1052 | K3: 655
A4: BLR-Narayanapura | B4: {=IF(A4="","",IFERROR(INDEX('CLM & IM Mapping'!$B$2:$B$270,MATCH(TRIM(A4),'CLM & IM Mapping'!$A$2:$A$270,0)),"Not Mapped"))} -> Adhavan Subramani | C4: {=IF(A4="","",IFERROR(INDEX('CLM & IM Mapping'!$C$2:$C$270,MATCH(TRIM(A4),'CLM & IM Mapping'!$A$2:$A$270,0)),"Not Mapped"))} -> Mohammed Akbar | D4: 48 | E4: 594 | F4: 2 | G4: 2 | H4: 12 | I4: 23 | J4: 681 | K4: 681
A5: BLR-Kannamangala | B5: {=IF(A5="","",IFERROR(INDEX('CLM & IM Mapping'!$B$2:$B$270,MATCH(TRIM(A5),'CLM & IM Mapping'!$A$2:$A$270,0)),"Not Mapped"))} -> Ashwath S | C5: {=IF(A5="","",IFERROR(INDEX('CLM & IM Mapping'!$C$2:$C$270,MATCH(TRIM(A5),'CLM & IM Mapping'!$A$2:$A$270,0)),"Not Mapped"))} -> Kantha Kumar | D5: 74 | E5: 398 | F5: 7 | G5: 3 | H5: 0 | I5: 191 | J5: 673 | K5: 429
A6: BLR-Brookfield Network-2 | B6: {=IF(A6="","",IFERROR(INDEX('CLM & IM Mapping'!$B$2:$B$270,MATCH(TRIM(A6),'CLM & IM Mapping'!$A$2:$A$270,0)),"Not Mapped"))} -> Silambarasan E | C6: {=IF(A6="","",IFERROR(INDEX('CLM & IM Mapping'!$C$2:$C$270,MATCH(TRIM(A6),'CLM & IM Mapping'!$A$2:$A$270,0)),"Not Mapped"))} -> Arivind S | D6: 172 | E6: 430 | F6: 11 | G6: 0 | H6: 15 | I6: 35 | J6: 663 | K6: 240
A7: BLR-Chamrajpet | B7: {=IF(A7="","",IFERROR(INDEX('CLM & IM Mapping'!$B$2:$B$270,MATCH(TRIM(A7),'CLM & IM Mapping'!$A$2:$A$270,0)),"Not Mapped"))} -> Narasimhamurthy R | C7: {=IF(A7="","",IFERROR(INDEX('CLM & IM Mapping'!$C$2:$C$270,MATCH(TRIM(A7),'CLM & IM Mapping'!$A$2:$A$270,0)),"Not Mapped"))} -> Kishor K | D7: 85 | E7: 401 | F7: 93 | G7: 3 | H7: 0 | I7: 76 | J7: 658 | K7: 399
A8: BLR-BASAVANAPURA | B8: {=IF(A8="","",IFERROR(INDEX('CLM & IM Mapping'!$B$2:$B$270,MATCH(TRIM(A8),'CLM & IM Mapping'!$A$2:$A$270,0)),"Not Mapped"))} -> Richard Harris | C8: {=IF(A8="","",IFERROR(INDEX('CLM & IM Mapping'!$C$2:$C$270,MATCH(TRIM(A8),'CLM & IM Mapping'!$A$2:$A$270,0)),"Not Mapped"))} -> Kantha Kumar | D8: 21 | E8: 85 | F8: 3 | G8: 377 | H8: 100 | I8: 42 | J8: 628 | K8: 203
